Workbook

Sheet Incident Reporting
A1: מספר סידורי | B1: מועד הפגיעה | C1: מועד דיווח | D1: שלב | E1: סוג פגיעה | F1: אופי הפגיעה | G1: תדירות הפגיעה | H1: פגיעה עקרית | I1: מועד פגיעה | J1: סוג מתקן | K1: שיטת טיפול | L1: דחיפות טיפול | M1: פרמטרים תומכים | N1: מסקנות | O1: חומרת מקרה | P1: חומרה רפואית | Q1: חומרה דוזימטרית | R1: חומרה כוללת | U1: הערות
A2: 1 | B2: 42005 | D2: מהלך טיפול | E2: נפגע | F2: נפגע יחיד | G2: חד פעמי | H2: תרבות עבודה | J2: מאיץ1/מאיץ2 | K2: SRS\SRT | L2: תיק מהיר | M2: פרמטר יחיד | N2: חידוד נהל קיים | O2: =IF(ISBLANK(D2),"",IF(D2='טבלת פרמטרים'!$A$9,1,0)+IF(E2='טבלת פרמטרים'!$B$5,2,1)+IF(F2='טבלת פרמטרים'!$C$5,3,IF(F2='טבלת פרמטרים'!$C$4,1,0))+IF(G2='טבלת פרמטרים'!$D$3,2,0)+IF(M2='טבלת פרמטרים'!$J$4,2,IF(M2='טבלת פרמטרים'!$J$3,1,0))+IF(N2='טבלת פרמטרים'!$K$6,3,IF(OR(N2='טבלת פרמטרים'!$K$4,N2='טבלת פרמטרים'!$K$5),2,IF(N2='טבלת פרמטרים'!$K$3,1,0)))) -> 6 | R2: =IF(ISNUMBER(T2),T2+O2,O2) -> 6 | S2: =IF(EXACT(P2,'טבלת פרמטרים'!$M$2),'טבלת פרמטרים'!$N$2,IF(EXACT(P2,'טבלת פרמטרים'!$M$3),'טבלת פרמטרים'!$N$3,IF(EXACT(P2,'טבלת פרמטרים'!$M$4),'טבלת פרמטרים'!$N$4,IF(EXACT(P2,'טבלת פרמטרים'!$M$5),'טבלת פרמטרים'!$N$5,IF(EXACT(P2,'טבלת פרמטרים'!$M$6),'טבלת פרמטרים'!$N$6,IF(EXACT(P2,'טבלת פרמטרים'!$M$7),'טבלת פרמטרים'!$N$7,IF(EXACT(P2,'טבלת פרמטרים'!$M$8),'טבלת פרמטרים'!$N$8,IF(EXACT(P2,'טבלת פרמטרים'!$M$9),'טבלת פרמטרים'!$N$9,"")))))))) | T2: =IF(EXACT(Q2,'טבלת פרמטרים'!$O$2),'טבלת פרמטרים'!$P$2,IF(EXACT(Q2,'טבלת פרמטרים'!$O$3),'טבלת פרמטרים'!$P$3,IF(EXACT(Q2,'טבלת פרמטרים'!$O$4),'טבלת פרמטרים'!$P$4,IF(EXACT(Q2,'טבלת פרמטרים'!$O$5),'טבלת פרמטרים'!$P$5,IF(EXACT(Q2,'טבלת פרמטרים'!$O$6),'טבלת פרמטרים'!$P$6,IF(EXACT(Q2,'טבלת פרמטרים'!$O$7),'טבלת פרמטרים'!$P$7,""))))))
A3: 2 | B3: 42008 | D3: לפני טיפול | E3: מקרה בטיחות | F3: ללא נפגעים | G3: חד פעמי | H3: תקשורת | J3: מאיץ4/מאיץ5 | K3: IMRT | L3: תיק רגיל | M3: ללא | N3: חידוד נהל קיים | O3: =IF(ISBLANK(D3),"",IF(D3='טבלת פרמטרים'!$A$9,1,0)+IF(E3='טבלת פרמטרים'!$B$5,2,1)+IF(F3='טבלת פרמטרים'!$C$5,3,IF(F3='טבלת פרמטרים'!$C$4,1,0))+IF(G3='טבלת פרמטרים'!$D$3,2,0)+IF(M3='טבלת פרמטרים'!$J$4,2,IF(M3='טבלת פרמטרים'!$J$3,1,0))+IF(N3='טבלת פרמטרים'!$K$6,3,IF(OR(N3='טבלת פרמטרים'!$K$4,N3='טבלת פרמטרים'!$K$5),2,IF(N3='טבלת פרמטרים'!$K$3,1,0)))) -> 2 | R3: =IF(ISNUMBER(T3),T3+O3,O3) -> 2 | S3: =IF(EXACT(P3,'טבלת פרמטרים'!$M$2),'טבלת פרמטרים'!$N$2,IF(EXACT(P3,'טבלת פרמטרים'!$M$3),'טבלת פרמטרים'!$N$3,IF(EXACT(P3,'טבלת פרמטרים'!$M$4),'טבלת פרמטרים'!$N$4,IF(EXACT(P3,'טבלת פרמטרים'!$M$5),'טבלת פרמטרים'!$N$5,IF(EXACT(P3,'טבלת פרמטרים'!$M$6),'טבלת פרמטרים'!$N$6,IF(EXACT(P3,'טבלת פרמטרים'!$M$7),'טבלת פרמטרים'!$N$7,IF(EXACT(P3,'טבלת פרמטרים'!$M$8),'טבלת פרמטרים'!$N$8,IF(EXACT(P3,'טבלת פרמטרים'!$M$9),'טבלת פרמטרים'!$N$9,"")))))))) | T3: =IF(EXACT(Q3,'טבלת פרמטרים'!$O$2),'טבלת פרמטרים'!$P$2,IF(EXACT(Q3,'טבלת פרמטרים'!$O$3),'טבלת פרמטרים'!$P$3,IF(EXACT(Q3,'טבלת פרמטרים'!$O$4),'טבלת פרמטרים'!$P$4,IF(EXACT(Q3,'טבלת פרמטרים'!$O$5),'טבלת פרמטרים'!$P$5,IF(EXACT(Q3,'טבלת פרמטרים'!$O$6),'טבלת פרמטרים'!$P$6,IF(EXACT(Q3,'טבלת פרמטרים'!$O$7),'טבלת פרמטרים'!$P$7,""))))))
A4: 3 | B4: 42022 | D4: מהלך טיפול | E4: כמעט נפגע | F4: נפגע יחיד | G4: חד פעמי | H4: נהל עבודה | J4: מאיץ3 | K4: 3D | L4: לא ישים | M4: ללא | N4: שינוי נוהל קיים | O4: =IF(ISBLANK(D4),"",IF(D4='טבלת פרמטרים'!$A$9,1,0)+IF(E4='טבלת פרמטרים'!$B$5,2,1)+IF(F4='טבלת פרמטרים'!$C$5,3,IF(F4='טבלת פרמטרים'!$C$4,1,0))+IF(G4='טבלת פרמטרים'!$D$3,2,0)+IF(M4='טבלת פרמטרים'!$J$4,2,IF(M4='טבלת פרמטרים'!$J$3,1,0))+IF(N4='טבלת פרמטרים'!$K$6,3,IF(OR(N4='טבלת פרמטרים'!$K$4,N4='טבלת פרמטרים'!$K$5),2,IF(N4='טבלת פרמטרים'!$K$3,1,0)))) -> 5 | R4: =IF(ISNUMBER(T4),T4+O4,O4) -> 5 | S4: =IF(EXACT(P4,'טבלת פרמטרים'!$M$2),'טבלת פרמטרים'!$N$2,IF(EXACT(P4,'טבלת פרמטרים'!$M$3),'טבלת פרמטרים'!$N$3,IF(EXACT(P4,'טבלת פרמטרים'!$M$4),'טבלת פרמטרים'!$N$4,IF(EXACT(P4,'טבלת פרמטרים'!$M$5),'טבלת פרמטרים'!$N$5,IF(EXACT(P4,'טבלת פרמטרים'!$M$6),'טבלת פרמטרים'!$N$6,IF(EXACT(P4,'טבלת פרמטרים'!$M$7),'טבלת פרמטרים'!$N$7,IF(EXACT(P4,'טבלת פרמטרים'!$M$8),'טבלת פרמטרים'!$N$8,IF(EXACT(P4,'טבלת פרמטרים'!$M$9),'טבלת פרמטרים'!$N$9,"")))))))) | T4: =IF(EXACT(Q4,'טבלת פרמטרים'!$O$2),'טבלת פרמטרים'!$P$2,IF(EXACT(Q4,'טבלת פרמטרים'!$O$3),'טבלת פרמטרים'!$P$3,IF(EXACT(Q4,'טבלת פרמטרים'!$O$4),'טבלת פרמטרים'!$P$4,IF(EXACT(Q4,'טבלת פרמטרים'!$O$5),'טבלת פרמטרים'!$P$5,IF(EXACT(Q4,'טבלת פרמטרים'!$O$6),'טבלת פרמטרים'!$P$6,IF(EXACT(Q4,'טבלת פרמטרים'!$O$7),'טבלת פרמטרים'!$P$7,""))))))
A5: 4 | B5: 42024 | D5: לפני טיפול | E5: מקרה בטיחות | F5: ללא נפגעים | G5: חד פעמי | H5: טעות אנוש | J5: מאיץ1/מאיץ2 | K5: IMRT | L5: תיק רגיל | M5: פרמטר יחיד | N5: ללא שינוי | O5: =IF(ISBLANK(D5),"",IF(D5='טבלת פרמטרים'!$A$9,1,0)+IF(E5='טבלת פרמטרים'!$B$5,2,1)+IF(F5='טבלת פרמטרים'!$C$5,3,IF(F5='טבלת פרמטרים'!$C$4,1,0))+IF(G5='טבלת פרמטרים'!$D$3,2,0)+IF(M5='טבלת פרמטרים'!$J$4,2,IF(M5='טבלת פרמטרים'!$J$3,1,0))+IF(N5='טבלת פרמטרים'!$K$6,3,IF(OR(N5='טבלת פרמטרים'!$K$4,N5='טבלת פרמטרים'!$K$5),2,IF(N5='טבלת פרמטרים'!$K$3,1,0)))) -> 2 | R5: =IF(ISNUMBER(T5),T5+O5,O5) -> 2 | S5: =IF(EXACT(P5,'טבלת פרמטרים'!$M$2),'טבלת פרמטרים'!$N$2,IF(EXACT(P5,'טבלת פרמטרים'!$M$3),'טבלת פרמטרים'!$N$3,IF(EXACT(P5,'טבלת פרמטרים'!$M$4),'טבלת פרמטרים'!$N$4,IF(EXACT(P5,'טבלת פרמטרים'!$M$5),'טבלת פרמטרים'!$N$5,IF(EXACT(P5,'טבלת פרמטרים'!$M$6),'טבלת פרמטרים'!$N$6,IF(EXACT(P5,'טבלת פרמטרים'!$M$7),'טבלת פרמטרים'!$N$7,IF(EXACT(P5,'טבלת פרמטרים'!$M$8),'טבלת פרמטרים'!$N$8,IF(EXACT(P5,'טבלת פרמטרים'!$M$9),'טבלת פרמטרים'!$N$9,"")))))))) | T5: =IF(EXACT(Q5,'טבלת פרמטרים'!$O$2),'טבלת פרמטרים'!$P$2,IF(EXACT(Q5,'טבלת פרמטרים'!$O$3),'טבלת פרמטרים'!$P$3,IF(EXACT(Q5,'טבלת פרמטרים'!$O$4),'טבלת פרמטרים'!$P$4,IF(EXACT(Q5,'טבלת פרמטרים'!$O$5),'טבלת פרמטרים'!$P$5,IF(EXACT(Q5,'טבלת פרמטרים'!$O$6),'טבלת פרמטרים'!$P$6,IF(EXACT(Q5,'טבלת פרמטרים'!$O$7),'טבלת פרמטרים'!$P$7,""))))))
A6: 5 | B6: 42024 | D6: מהלך טיפול | E6: מקרה בטיחות | F6: ללא נפגעים | G6: חד פעמי | H6: תקשורת | J6: מאיץ1/מאיץ2 | K6: IMRT | L6: תיק רגיל | M6: פרמטר יחיד | N6: ללא שינוי | O6: =IF(ISBLANK(D6),"",IF(D6='טבלת פרמטרים'!$A$9,1,0)+IF(E6='טבלת פרמטרים'!$B$5,2,1)+IF(F6='טבלת פרמטרים'!$C$5,3,IF(F6='טבלת פרמטרים'!$C$4,1,0))+IF(G6='טבלת פרמטרים'!$D$3,2,0)+IF(M6='טבלת פרמטרים'!$J$4,2,IF(M6='טבלת פרמטרים'!$J$3,1,0))+IF(N6='טבלת פרמטרים'!$K$6,3,IF(OR(N6='טבלת פרמטרים'!$K$4,N6='טבלת פרמטרים'!$K$5),2,IF(N6='טבלת פרמטרים'!$K$3,1,0)))) -> 3 | R6: =IF(ISNUMBER(T6),T6+O6,O6) -> 3 | S6: =IF(EXACT(P6,'טבלת פרמטרים'!$M$2),'טבלת פרמטרים'!$N$2,IF(EXACT(P6,'טבלת פרמטרים'!$M$3),'טבלת פרמטרים'!$N$3,IF(EXACT(P6,'טבלת פרמטרים'!$M$4),'טבלת פרמטרים'!$N$4,IF(EXACT(P6,'טבלת פרמטרים'!$M$5),'טבלת פרמטרים'!$N$5,IF(EXACT(P6,'טבלת פרמטרים'!$M$6),'טבלת פרמטרים'!$N$6,IF(EXACT(P6,'טבלת פרמטרים'!$M$7),'טבלת פרמטרים'!$N$7,IF(EXACT(P6,'טבלת פרמטרים'!$M$8),'טבלת פרמטרים'!$N$8,IF(EXACT(P6,'טבלת פרמטרים'!$M$9),'טבלת פרמטרים'!$N$9,"")))))))) | T6: =IF(EXACT(Q6,'טבלת פרמטרים'!$O$2),'טבלת פרמטרים'!$P$2,IF(EXACT(Q6,'טבלת פרמטרים'!$O$3),'טבלת פרמטרים'!$P$3,IF(EXACT(Q6,'טבלת פרמטרים'!$O$4),'טבלת פרמטרים'!$P$4,IF(EXACT(Q6,'טבלת פרמטרים'!$O$5),'טבלת פרמטרים'!$P$5,IF(EXACT(Q6,'טבלת פרמטרים'!$O$6),'טבלת פרמטרים'!$P$6,IF(EXACT(Q6,'טבלת פרמטרים'!$O$7),'טבלת פרמטרים'!$P$7,""))))))
A7: 6 | B7: 42089 | D7: מהלך טיפול | E7: נפגע | F7: נפגע יחיד | G7: חד פעמי | H7: טעות אנוש | J7: מאיץ4/מאיץ5 | K7: 3D | L7: תיק רגיל | M7: יותר מפרמטר אחד | N7: חידוד נהל קיים | O7: =IF(ISBLANK(D7),"",IF(D7='טבלת פרמטרים'!$A$9,1,0)+IF(E7='טבלת פרמטרים'!$B$5,2,1)+IF(F7='טבלת פרמטרים'!$C$5,3,IF(F7='טבלת פרמטרים'!$C$4,1,0))+IF(G7='טבלת פרמטרים'!$D$3,2,0)+IF(M7='טבלת פרמטרים'!$J$4,2,IF(M7='טבלת פרמטרים'!$J$3,1,0))+IF(N7='טבלת פרמטרים'!$K$6,3,IF(OR(N7='טבלת פרמטרים'!$K$4,N7='טבלת פרמטרים'!$K$5),2,IF(N7='טבלת פרמטרים'!$K$3,1,0)))) -> 7 | R7: =IF(ISNUMBER(T7),T7+O7,O7) -> 7 | S7: =IF(EXACT(P7,'טבלת פרמטרים'!$M$2),'טבלת פרמטרים'!$N$2,IF(EXACT(P7,'טבלת פרמטרים'!$M$3),'טבלת פרמטרים'!$N$3,IF(EXACT(P7,'טבלת פרמטרים'!$M$4),'טבלת פרמטרים'!$N$4,IF(EXACT(P7,'טבלת פרמטרים'!$M$5),'טבלת פרמטרים'!$N$5,IF(EXACT(P7,'טבלת פרמטרים'!$M$6),'טבלת פרמטרים'!$N$6,IF(EXACT(P7,'טבלת פרמטרים'!$M$7),'טבלת פרמטרים'!$N$7,IF(EXACT(P7,'טבלת פרמטרים'!$M$8),'טבלת פרמטרים'!$N$8,IF(EXACT(P7,'טבלת פרמטרים'!$M$9),'טבלת פרמטרים'!$N$9,"")))))))) | T7: =IF(EXACT(Q7,'טבלת פרמטרים'!$O$2),'טבלת פרמטרים'!$P$2,IF(EXACT(Q7,'טבלת פרמטרים'!$O$3),'טבלת פרמטרים'!$P$3,IF(EXACT(Q7,'טבלת פרמטרים'!$O$4),'טבלת פרמטרים'!$P$4,IF(EXACT(Q7,'טבלת פרמטרים'!$O$5),'טבלת פרמטרים'!$P$5,IF(EXACT(Q7,'טבלת פרמטרים'!$O$6),'טבלת פרמטרים'!$P$6,IF(EXACT(Q7,'טבלת פרמטרים'!$O$7),'טבלת פרמטרים'!$P$7,""))))))
A8: 7 | B8: 42121 | D8: מהלך טיפול | E8: נפגע | F8: נפגע יחיד | G8: חד פעמי | H8: תרבות עבודה | J8: מאיץ3 | K8: 3D | L8: תיק דחוף | M8: ללא | N8: חידוד נהל קיים | O8: =IF(ISBLANK(D8),"",IF(D8='טבלת פרמטרים'!$A$9,1,0)+IF(E8='טבלת פרמטרים'!$B$5,2,1)+IF(F8='טבלת פרמטרים'!$C$5,3,IF(F8='טבלת פרמטרים'!$C$4,1,0))+IF(G8='טבלת פרמטרים'!$D$3,2,0)+IF(M8='טבלת פרמטרים'!$J$4,2,IF(M8='טבלת פרמטרים'!$J$3,1,0))+IF(N8='טבלת פרמטרים'!$K$6,3,IF(OR(N8='טבלת פרמטרים'!$K$4,N8='טבלת פרמטרים'!$K$5),2,IF(N8='טבלת פרמטרים'!$K$3,1,0)))) -> 5 | R8: =IF(ISNUMBER(T8),T8+O8,O8) -> 5 | S8: =IF(EXACT(P8,'טבלת פרמטרים'!$M$2),'טבלת פרמטרים'!$N$2,IF(EXACT(P8,'טבלת פרמטרים'!$M$3),'טבלת פרמטרים'!$N$3,IF(EXACT(P8,'טבלת פרמטרים'!$M$4),'טבלת פרמטרים'!$N$4,IF(EXACT(P8,'טבלת פרמטרים'!$M$5),'טבלת פרמטרים'!$N$5,IF(EXACT(P8,'טבלת פרמטרים'!$M$6),'טבלת פרמטרים'!$N$6,IF(EXACT(P8,'טבלת פרמטרים'!$M$7),'טבלת פרמטרים'!$N$7,IF(EXACT(P8,'טבלת פרמטרים'!$M$8),'טבלת פרמטרים'!$N$8,IF(EXACT(P8,'טבלת פרמטרים'!$M$9),'טבלת פרמטרים'!$N$9,"")))))))) | T8: =IF(EXACT(Q8,'טבלת פרמטרים'!$O$2),'טבלת פרמטרים'!$P$2,IF(EXACT(Q8,'טבלת פרמטרים'!$O$3),'טבלת פרמטרים'!$P$3,IF(EXACT(Q8,'טבלת פרמטרים'!$O$4),'טבלת פרמטרים'!$P$4,IF(EXACT(Q8,'טבלת פרמטרים'!$O$5),'טבלת פרמטרים'!$P$5,IF(EXACT(Q8,'טבלת פרמטרים'!$O$6),'טבלת פרמטרים'!$P$6,IF(EXACT(Q8,'טבלת פרמטרים'!$O$7),'טבלת פרמטרים'!$P$7,""))))))
A9: 8 | B9: 42156 | D9: מהלך טיפול | E9: מקרה בטיחות | F9: נפגע יחיד | G9: חד פעמי | H9: תקשורת | J9: מאיץ1/מאיץ2 | K9: IMRT | L9: תיק רגיל | M9: פרמטר יחיד | N9: ללא שינוי | O9: =IF(ISBLANK(D9),"",IF(D9='טבלת פרמטרים'!$A$9,1,0)+IF(E9='טבלת פרמטרים'!$B$5,2,1)+IF(F9='טבלת פרמטרים'!$C$5,3,IF(F9='טבלת פרמטרים'!$C$4,1,0))+IF(G9='טבלת פרמטרים'!$D$3,2,0)+IF(M9='טבלת פרמטרים'!$J$4,2,IF(M9='טבלת פרמטרים'!$J$3,1,0))+IF(N9='טבלת פרמטרים'!$K$6,3,IF(OR(N9='טבלת פרמטרים'!$K$4,N9='טבלת פרמטרים'!$K$5),2,IF(N9='טבלת פרמטרים'!$K$3,1,0)))) -> 4 | R9: =IF(ISNUMBER(T9),T9+O9,O9) -> 4 | S9: =IF(EXACT(P9,'טבלת פרמטרים'!$M$2),'טבלת פרמטרים'!$N$2,IF(EXACT(P9,'טבלת פרמטרים'!$M$3),'טבלת פרמטרים'!$N$3,IF(EXACT(P9,'טבלת פרמטרים'!$M$4),'טבלת פרמטרים'!$N$4,IF(EXACT(P9,'טבלת פרמטרים'!$M$5),'טבלת פרמטרים'!$N$5,IF(EXACT(P9,'טבלת פרמטרים'!$M$6),'טבלת פרמטרים'!$N$6,IF(EXACT(P9,'טבלת פרמטרים'!$M$7),'טבלת פרמטרים'!$N$7,IF(EXACT(P9,'טבלת פרמטרים'!$M$8),'טבלת פרמטרים'!$N$8,IF(EXACT(P9,'טבלת פרמטרים'!$M$9),'טבלת פרמטרים'!$N$9,"")))))))) | T9: =IF(EXACT(Q9,'טבלת פרמטרים'!$O$2),'טבלת פרמטרים'!$P$2,IF(EXACT(Q9,'טבלת פרמטרים'!$O$3),'טבלת פרמטרים'!$P$3,IF(EXACT(Q9,'טבלת פרמטרים'!$O$4),'טבלת פרמטרים'!$P$4,IF(EXACT(Q9,'טבלת פרמטרים'!$O$5),'טבלת פרמטרים'!$P$5,IF(EXACT(Q9,'טבלת פרמטרים'!$O$6),'טבלת פרמטרים'!$P$6,IF(EXACT(Q9,'טבלת פרמטרים'!$O$7),'טבלת פרמטרים'!$P$7,""))))))
A10: 9 | B10: 42173 | D10: מהלך טיפול | E10: נפגע | F10: נפגע יחיד | G10: חד פעמי | H10: תקשורת | J10: מאיץ4/מאיץ5 | K10: IMRT | L10: תיק רגיל | M10: פרמטר יחיד | N10: חידוד נהל קיים | O10: =IF(ISBLANK(D10),"",IF(D10='טבלת פרמטרים'!$A$9,1,0)+IF(E10='טבלת פרמטרים'!$B$5,2,1)+IF(F10='טבלת פרמטרים'!$C$5,3,IF(F10='טבלת פרמטרים'!$C$4,1,0))+IF(G10='טבלת פרמטרים'!$D$3,2,0)+IF(M10='טבלת פרמטרים'!$J$4,2,IF(M10='טבלת פרמטרים'!$J$3,1,0))+IF(N10='טבלת פרמטרים'!$K$6,3,IF(OR(N10='טבלת פרמטרים'!$K$4,N10='טבלת פרמטרים'!$K$5),2,IF(N10='טבלת פרמטרים'!$K$3,1,0)))) -> 6 | R10: =IF(ISNUMBER(T10),T10+O10,O10) -> 6 | S10: =IF(EXACT(P10,'טבלת פרמטרים'!$M$2),'טבלת פרמטרים'!$N$2,IF(EXACT(P10,'טבלת פרמטרים'!$M$3),'טבלת פרמטרים'!$N$3,IF(EXACT(P10,'טבלת פרמטרים'!$M$4),'טבלת פרמטרים'!$N$4,IF(EXACT(P10,'טבלת פרמטרים'!$M$5),'טבלת פרמטרים'!$N$5,IF(EXACT(P10,'טבלת פרמטרים'!$M$6),'טבלת פרמטרים'!$N$6,IF(EXACT(P10,'טבלת פרמטרים'!$M$7),'טבלת פרמטרים'!$N$7,IF(EXACT(P10,'טבלת פרמטרים'!$M$8),'טבלת פרמטרים'!$N$8,IF(EXACT(P10,'טבלת פרמטרים'!$M$9),'טבלת פרמטרים'!$N$9,"")))))))) | T10: =IF(EXACT(Q10,'טבלת פרמטרים'!$O$2),'טבלת פרמטרים'!$P$2,IF(EXACT(Q10,'טבלת פרמטרים'!$O$3),'טבלת פרמטרים'!$P$3,IF(EXACT(Q10,'טבלת פרמטרים'!$O$4),'טבלת פרמטרים'!$P$4,IF(EXACT(Q10,'טבלת פרמטרים'!$O$5),'טבלת פרמטרים'!$P$5,IF(EXACT(Q10,'טבלת פרמטרים'!$O$6),'טבלת פרמטרים'!$P$6,IF(EXACT(Q10,'טבלת פרמטרים'!$O$7),'טבלת פרמטרים'!$P$7,""))))))
A11: 10 | B11: 42198 | D11: לפני טיפול | E11: מקרה בטיחות | F11: ללא נפגעים | G11: חד פעמי | H11: תקשורת | J11: מאיץ3 | K11: 3D | L11: תיק רגיל | M11: פרמטר יחיד | N11: ללא שינוי | O11: =IF(ISBLANK(D11),"",IF(D11='טבלת פרמטרים'!$A$9,1,0)+IF(E11='טבלת פרמטרים'!$B$5,2,1)+IF(F11='טבלת פרמטרים'!$C$5,3,IF(F11='טבלת פרמטרים'!$C$4,1,0))+IF(G11='טבלת פרמטרים'!$D$3,2,0)+IF(M11='טבלת פרמטרים'!$J$4,2,IF(M11='טבלת פרמטרים'!$J$3,1,0))+IF(N11='טבלת פרמטרים'!$K$6,3,IF(OR(N11='טבלת פרמטרים'!$K$4,N11='טבלת פרמטרים'!$K$5),2,IF(N11='טבלת פרמטרים'!$K$3,1,0)))) -> 2 | R11: =IF(ISNUMBER(T11),T11+O11,O11) -> 2 | S11: =IF(EXACT(P11,'טבלת פרמטרים'!$M$2),'טבלת פרמטרים'!$N$2,IF(EXACT(P11,'טבלת פרמטרים'!$M$3),'טבלת פרמטרים'!$N$3,IF(EXACT(P11,'טבלת פרמטרים'!$M$4),'טבלת פרמטרים'!$N$4,IF(EXACT(P11,'טבלת פרמטרים'!$M$5),'טבלת פרמטרים'!$N$5,IF(EXACT(P11,'טבלת פרמטרים'!$M$6),'טבלת פרמטרים'!$N$6,IF(EXACT(P11,'טבלת פרמטרים'!$M$7),'טבלת פרמטרים'!$N$7,IF(EXACT(P11,'טבלת פרמטרים'!$M$8),'טבלת פרמטרים'!$N$8,IF(EXACT(P11,'טבלת פרמטרים'!$M$9),'טבלת פרמטרים'!$N$9,"")))))))) | T11: =IF(EXACT(Q11,'טבלת פרמטרים'!$O$2),'טבלת פרמטרים'!$P$2,IF(EXACT(Q11,'טבלת פרמטרים'!$O$3),'טבלת פרמטרים'!$P$3,IF(EXACT(Q11,'טבלת פרמטרים'!$O$4),'טבלת פרמטרים'!$P$4,IF(EXACT(Q11,'טבלת פרמטרים'!$O$5),'טבלת פרמטרים'!$P$5,IF(EXACT(Q11,'טבלת פרמטרים'!$O$6),'טבלת פרמטרים'!$P$6,IF(EXACT(Q11,'טבלת פרמטרים'!$O$7),'טבלת פרמטרים'!$P$7,""))))))
A12: 11 | B12: 42212 | D12: מהלך טיפול | E12: נפגע | F12: נפגע יחיד | G12: חד פעמי | H12: תקשורת | J12: ברכיתרפיה | K12: ברכיתרפיה | L12: תיק רגיל | M12: יותר מפרמטר אחד | N12: חידוד נהל קיים | O12: =IF(ISBLANK(D12),"",IF(D12='טבלת פרמטרים'!$A$9,1,0)+IF(E12='טבלת פרמטרים'!$B$5,2,1)+IF(F12='טבלת פרמטרים'!$C$5,3,IF(F12='טבלת פרמטרים'!$C$4,1,0))+IF(G12='טבלת פרמטרים'!$D$3,2,0)+IF(M12='טבלת פרמטרים'!$J$4,2,IF(M12='טבלת פרמטרים'!$J$3,1,0))+IF(N12='טבלת פרמטרים'!$K$6,3,IF(OR(N12='טבלת פרמטרים'!$K$4,N12='טבלת פרמטרים'!$K$5),2,IF(N12='טבלת פרמטרים'!$K$3,1,0)))) -> 7 | R12: =IF(ISNUMBER(T12),T12+O12,O12) -> 7 | S12: =IF(EXACT(P12,'טבלת פרמטרים'!$M$2),'טבלת פרמטרים'!$N$2,IF(EXACT(P12,'טבלת פרמטרים'!$M$3),'טבלת פרמטרים'!$N$3,IF(EXACT(P12,'טבלת פרמטרים'!$M$4),'טבלת פרמטרים'!$N$4,IF(EXACT(P12,'טבלת פרמטרים'!$M$5),'טבלת פרמטרים'!$N$5,IF(EXACT(P12,'טבלת פרמטרים'!$M$6),'טבלת פרמטרים'!$N$6,IF(EXACT(P12,'טבלת פרמטרים'!$M$7),'טבלת פרמטרים'!$N$7,IF(EXACT(P12,'טבלת פרמטרים'!$M$8),'טבלת פרמטרים'!$N$8,IF(EXACT(P12,'טבלת פרמטרים'!$M$9),'טבלת פרמטרים'!$N$9,"")))))))) | T12: =IF(EXACT(Q12,'טבלת פרמטרים'!$O$2),'טבלת פרמטרים'!$P$2,IF(EXACT(Q12,'טבלת פרמטרים'!$O$3),'טבלת פרמטרים'!$P$3,IF(EXACT(Q12,'טבלת פרמטרים'!$O$4),'טבלת פרמטרים'!$P$4,IF(EXACT(Q12,'טבלת פרמטרים'!$O$5),'טבלת פרמטרים'!$P$5,IF(EXACT(Q12,'טבלת פרמטרים'!$O$6),'טבלת פרמטרים'!$P$6,IF(EXACT(Q12,'טבלת פרמטרים'!$O$7),'טבלת פרמטרים'!$P$7,""))))))
A13: 12 | B13: 42226 | D13: מהלך טיפול | E13: מקרה בטיחות | F13: נפגע יחיד | G13: חד פעמי | H13: טעות אנוש | J13: מאיץ4/מאיץ5 | K13: 3D | L13: תיק רגיל | M13: ללא | N13: חידוד נהל קיים | O13: =IF(ISBLANK(D13),"",IF(D13='טבלת פרמטרים'!$A$9,1,0)+IF(E13='טבלת פרמטרים'!$B$5,2,1)+IF(F13='טבלת פרמטרים'!$C$5,3,IF(F13='טבלת פרמטרים'!$C$4,1,0))+IF(G13='טבלת פרמטרים'!$D$3,2,0)+IF(M13='טבלת פרמטרים'!$J$4,2,IF(M13='טבלת פרמטרים'!$J$3,1,0))+IF(N13='טבלת פרמטרים'!$K$6,3,IF(OR(N13='טבלת פרמטרים'!$K$4,N13='טבלת פרמטרים'!$K$5),2,IF(N13='טבלת פרמטרים'!$K$3,1,0)))) -> 4 | R13: =IF(ISNUMBER(T13),T13+O13,O13) -> 4 | S13: =IF(EXACT(P13,'טבלת פרמטרים'!$M$2),'טבלת פרמטרים'!$N$2,IF(EXACT(P13,'טבלת פרמטרים'!$M$3),'טבלת פרמטרים'!$N$3,IF(EXACT(P13,'טבלת פרמטרים'!$M$4),'טבלת פרמטרים'!$N$4,IF(EXACT(P13,'טבלת פרמטרים'!$M$5),'טבלת פרמטרים'!$N$5,IF(EXACT(P13,'טבלת פרמטרים'!$M$6),'טבלת פרמטרים'!$N$6,IF(EXACT(P13,'טבלת פרמטרים'!$M$7),'טבלת פרמטרים'!$N$7,IF(EXACT(P13,'טבלת פרמטרים'!$M$8),'טבלת פרמטרים'!$N$8,IF(EXACT(P13,'טבלת פרמטרים'!$M$9),'טבלת פרמטרים'!$N$9,"")))))))) | T13: =IF(EXACT(Q13,'טבלת פרמטרים'!$O$2),'טבלת פרמטרים'!$P$2,IF(EXACT(Q13,'טבלת פרמטרים'!$O$3),'טבלת פרמטרים'!$P$3,IF(EXACT(Q13,'טבלת פרמטרים'!$O$4),'טבלת פרמטרים'!$P$4,IF(EXACT(Q13,'טבלת פרמטרים'!$O$5),'טבלת פרמטרים'!$P$5,IF(EXACT(Q13,'טבלת פרמטרים'!$O$6),'טבלת פרמטרים'!$P$6,IF(EXACT(Q13,'טבלת פרמטרים'!$O$7),'טבלת פרמטרים'!$P$7,""))))))
... A40: 39 | B40: 43030 | D40: בקרת איכות | E40: כמעט נפגע | F40: ללא נפגעים | G40: חד פעמי | H40: טעות אנוש | J40: מאיץ3 | K40: IMRT | L40: תיק רגיל | M40: ללא | N40: ללא שינוי | O40: =IF(ISBLANK(D40),"",IF(D40='טבלת פרמטרים'!$A$9,1,0)+IF(E40='טבלת פרמטרים'!$B$5,2,1)+IF(F40='טבלת פרמטרים'!$C$5,3,IF(F40='טבלת פרמטרים'!$C$4,1,0))+IF(G40='טבלת פרמטרים'!$D$3,2,0)+IF(M40='טבלת פרמטרים'!$J$4,2,IF(M40='טבלת פרמטרים'!$J$3,1,0))+IF(N40='טבלת פרמטרים'!$K$6,3,IF(OR(N40='טבלת פרמטרים'!$K$4,N40='טבלת פרמטרים'!$K$5),2,IF(N40='טבלת פרמטרים'!$K$3,1,0)))) -> 1 | R40: =IF(ISNUMBER(T40),T40+O40,O40) -> 1 | S40: =IF(EXACT(P40,'טבלת פרמטרים'!$M$2),'טבלת פרמטרים'!$N$2,IF(EXACT(P40,'טבלת פרמטרים'!$M$3),'טבלת פרמטרים'!$N$3,IF(EXACT(P40,'טבלת פרמטרים'!$M$4),'טבלת פרמטרים'!$N$4,IF(EXACT(P40,'טבלת פרמטרים'!$M$5),'טבלת פרמטרים'!$N$5,IF(EXACT(P40,'טבלת פרמטרים'!$M$6),'טבלת פרמטרים'!$N$6,IF(EXACT(P40,'טבלת פרמטרים'!$M$7),'טבלת פרמטרים'!$N$7,IF(EXACT(P40,'טבלת פרמטרים'!$M$8),'טבלת פרמטרים'!$N$8,IF(EXACT(P40,'טבלת פרמטרים'!$M$9),'טבלת פרמטרים'!$N$9,"")))))))) | T40: =IF(EXACT(Q40,'טבלת פרמטרים'!$O$2),'טבלת פרמטרים'!$P$2,IF(EXACT(Q40,'טבלת פרמטרים'!$O$3),'טבלת פרמטרים'!$P$3,IF(EXACT(Q40,'טבלת פרמטרים'!$O$4),'טבלת פרמטרים'!$P$4,IF(EXACT(Q40,'טבלת פרמטרים'!$O$5),'טבלת פרמטרים'!$P$5,IF(EXACT(Q40,'טבלת פרמטרים'!$O$6),'טבלת פרמטרים'!$P$6,IF(EXACT(Q40,'טבלת פרמטרים'!$O$7),'טבלת פרמטרים'!$P$7,""))))))
A41: 40 | B41: 43025 | D41: מרשם | E41: נפגע | F41: נפגע יחיד | G41: חד פעמי | H41: תרבות עבודה | I41: עבודת בוקר | J41: ברכיתרפיה | K41: ברכיתרפיה | L41: תיק דחוף | M41: ללא | N41: ללא שינוי | O41: =IF(ISBLANK(D41),"",IF(D41='טבלת פרמטרים'!$A$9,1,0)+IF(E41='טבלת פרמטרים'!$B$5,2,1)+IF(F41='טבלת פרמטרים'!$C$5,3,IF(F41='טבלת פרמטרים'!$C$4,1,0))+IF(G41='טבלת פרמטרים'!$D$3,2,0)+IF(M41='טבלת פרמטרים'!$J$4,2,IF(M41='טבלת פרמטרים'!$J$3,1,0))+IF(N41='טבלת פרמטרים'!$K$6,3,IF(OR(N41='טבלת פרמטרים'!$K$4,N41='טבלת פרמטרים'!$K$5),2,IF(N41='טבלת פרמטרים'!$K$3,1,0)))) -> 3 | P41: לא נפגע | Q41: לא רלוונטי | R41: =IF(ISNUMBER(T41),T41+O41,O41) -> 3 | S41: =IF(EXACT(P41,'טבלת פרמטרים'!$M$2),'טבלת פרמטרים'!$N$2,IF(EXACT(P41,'טבלת פרמטרים'!$M$3),'טבלת פרמטרים'!$N$3,IF(EXACT(P41,'טבלת פרמטרים'!$M$4),'טבלת פרמטרים'!$N$4,IF(EXACT(P41,'טבלת פרמטרים'!$M$5),'טבלת פרמטרים'!$N$5,IF(EXACT(P41,'טבלת פרמטרים'!$M$6),'טבלת פרמטרים'!$N$6,IF(EXACT(P41,'טבלת פרמטרים'!$M$7),'טבלת פרמטרים'!$N$7,IF(EXACT(P41,'טבלת פרמטרים'!$M$8),'טבלת פרמטרים'!$N$8,IF(EXACT(P41,'טבלת פרמטרים'!$M$9),'טבלת פרמטרים'!$N$9,"")))))))) -> 0 | T41: =IF(EXACT(Q41,'טבלת פרמטרים'!$O$2),'טבלת פרמטרים'!$P$2,IF(EXACT(Q41,'טבלת פרמטרים'!$O$3),'טבלת פרמטרים'!$P$3,IF(EXACT(Q41,'טבלת פרמטרים'!$O$4),'טבלת פרמטרים'!$P$4,IF(EXACT(Q41,'טבלת פרמטרים'!$O$5),'טבלת פרמטרים'!$P$5,IF(EXACT(Q41,'טבלת פרמטרים'!$O$6),'טבלת פרמטרים'!$P$6,IF(EXACT(Q41,'טבלת פרמטרים'!$O$7),'טבלת פרמטרים'!$P$7,"")))))) -> 0
A42: 41 | B42: 43023 | D42: מרשם | E42: כמעט נפגע | F42: ללא נפגעים | G42: חד פעמי | H42: תרבות עבודה | I42: עבודת ערב | J42: מאיץ4/מאיץ5 | K42: סימון קליני | L42: תיק רגיל | M42: יותר מפרמטר אחד | N42: חידוד נהל קיים | O42: =IF(ISBLANK(D42),"",IF(D42='טבלת פרמטרים'!$A$9,1,0)+IF(E42='טבלת פרמטרים'!$B$5,2,1)+IF(F42='טבלת פרמטרים'!$C$5,3,IF(F42='טבלת פרמטרים'!$C$4,1,0))+IF(G42='טבלת פרמטרים'!$D$3,2,0)+IF(M42='טבלת פרמטרים'!$J$4,2,IF(M42='טבלת פרמטרים'!$J$3,1,0))+IF(N42='טבלת פרמטרים'!$K$6,3,IF(OR(N42='טבלת פרמטרים'!$K$4,N42='טבלת פרמטרים'!$K$5),2,IF(N42='טבלת פרמטרים'!$K$3,1,0)))) -> 4 | R42: =IF(ISNUMBER(T42),T42+O42,O42) -> 4 | S42: =IF(EXACT(P42,'טבלת פרמטרים'!$M$2),'טבלת פרמטרים'!$N$2,IF(EXACT(P42,'טבלת פרמטרים'!$M$3),'טבלת פרמטרים'!$N$3,IF(EXACT(P42,'טבלת פרמטרים'!$M$4),'טבלת פרמטרים'!$N$4,IF(EXACT(P42,'טבלת פרמטרים'!$M$5),'טבלת פרמטרים'!$N$5,IF(EXACT(P42,'טבלת פרמטרים'!$M$6),'טבלת פרמטרים'!$N$6,IF(EXACT(P42,'טבלת פרמטרים'!$M$7),'טבלת פרמטרים'!$N$7,IF(EXACT(P42,'טבלת פרמטרים'!$M$8),'טבלת פרמטרים'!$N$8,IF(EXACT(P42,'טבלת פרמטרים'!$M$9),'טבלת פרמטרים'!$N$9,"")))))))) | T42: =IF(EXACT(Q42,'טבלת פרמטרים'!$O$2),'טבלת פרמטרים'!$P$2,IF(EXACT(Q42,'טבלת פרמטרים'!$O$3),'טבלת פרמטרים'!$P$3,IF(EXACT(Q42,'טבלת פרמטרים'!$O$4),'טבלת פרמטרים'!$P$4,IF(EXACT(Q42,'טבלת פרמטרים'!$O$5),'טבלת פרמטרים'!$P$5,IF(EXACT(Q42,'טבלת פרמטרים'!$O$6),'טבלת פרמטרים'!$P$6,IF(EXACT(Q42,'טבלת פרמטרים'!$O$7),'טבלת פרמטרים'!$P$7,""))))))
A43: 42 | B43: 43018 | D43: מהלך טיפול | E43: נפגע | F43: נפגע יחיד | G43: חד פעמי | H43: טעות אנוש | I43: עבודת בוקר | J43: מאיץ1/מאיץ2 | K43: IMRT | L43: תיק רגיל | M43: יותר מפרמטר אחד | N43: שינוי נוהל קיים | O43: =IF(ISBLANK(D43),"",IF(D43='טבלת פרמטרים'!$A$9,1,0)+IF(E43='טבלת פרמטרים'!$B$5,2,1)+IF(F43='טבלת פרמטרים'!$C$5,3,IF(F43='טבלת פרמטרים'!$C$4,1,0))+IF(G43='טבלת פרמטרים'!$D$3,2,0)+IF(M43='טבלת פרמטרים'!$J$4,2,IF(M43='טבלת פרמטרים'!$J$3,1,0))+IF(N43='טבלת פרמטרים'!$K$6,3,IF(OR(N43='טבלת פרמטרים'!$K$4,N43='טבלת פרמטרים'!$K$5),2,IF(N43='טבלת פרמטרים'!$K$3,1,0)))) -> 8 | P43: לא נפגע | Q43: שוני במנה אבסולוטית מהמרשם קטן מ- 5% לכל איבר | R43: =IF(ISNUMBER(T43),T43+O43,O43) -> 9 | S43: =IF(EXACT(P43,'טבלת פרמטרים'!$M$2),'טבלת פרמטרים'!$N$2,IF(EXACT(P43,'טבלת פרמטרים'!$M$3),'טבלת פרמטרים'!$N$3,IF(EXACT(P43,'טבלת פרמטרים'!$M$4),'טבלת פרמטרים'!$N$4,IF(EXACT(P43,'טבלת פרמטרים'!$M$5),'טבלת פרמטרים'!$N$5,IF(EXACT(P43,'טבלת פרמטרים'!$M$6),'טבלת פרמטרים'!$N$6,IF(EXACT(P43,'טבלת פרמטרים'!$M$7),'טבלת פרמטרים'!$N$7,IF(EXACT(P43,'טבלת פרמטרים'!$M$8),'טבלת פרמטרים'!$N$8,IF(EXACT(P43,'טבלת פרמטרים'!$M$9),'טבלת פרמטרים'!$N$9,"")))))))) -> 0 | T43: =IF(EXACT(Q43,'טבלת פרמטרים'!$O$2),'טבלת פרמטרים'!$P$2,IF(EXACT(Q43,'טבלת פרמטרים'!$O$3),'טבלת פרמטרים'!$P$3,IF(EXACT(Q43,'טבלת פרמטרים'!$O$4),'טבלת פרמטרים'!$P$4,IF(EXACT(Q43,'טבלת פרמטרים'!$O$5),'טבלת פרמטרים'!$P$5,IF(EXACT(Q43,'טבלת פרמטרים'!$O$6),'טבלת פרמטרים'!$P$6,IF(EXACT(Q43,'טבלת פרמטרים'!$O$7),'טבלת פרמטרים'!$P$7,"")))))) -> 1
A44: 43 | B44: 43051 | D44: בקרת איכות | E44: מקרה בטיחות | F44: ללא נפגעים | G44: רב פעמי | H44: טעות אנוש | I44: עבודת בוקר | J44: מאיץ4/מאיץ5 | K44: 3D | L44: תיק רגיל | M44: יותר מפרמטר אחד | N44: חידוד נהל קיים | O44: =IF(ISBLANK(D44),"",IF(D44='טבלת פרמטרים'!$A$9,1,0)+IF(E44='טבלת פרמטרים'!$B$5,2,1)+IF(F44='טבלת פרמטרים'!$C$5,3,IF(F44='טבלת פרמטרים'!$C$4,1,0))+IF(G44='טבלת פרמטרים'!$D$3,2,0)+IF(M44='טבלת פרמטרים'!$J$4,2,IF(M44='טבלת פרמטרים'!$J$3,1,0))+IF(N44='טבלת פרמטרים'!$K$6,3,IF(OR(N44='טבלת פרמטרים'!$K$4,N44='טבלת פרמטרים'!$K$5),2,IF(N44='טבלת פרמטרים'!$K$3,1,0)))) -> 6 | P44: לא נפגע | Q44: לא רלוונטי | R44: =IF(ISNUMBER(T44),T44+O44,O44) -> 6 | S44: =IF(EXACT(P44,'טבלת פרמטרים'!$M$2),'טבלת פרמטרים'!$N$2,IF(EXACT(P44,'טבלת פרמטרים'!$M$3),'טבלת פרמטרים'!$N$3,IF(EXACT(P44,'טבלת פרמטרים'!$M$4),'טבלת פרמטרים'!$N$4,IF(EXACT(P44,'טבלת פרמטרים'!$M$5),'טבלת פרמטרים'!$N$5,IF(EXACT(P44,'טבלת פרמטרים'!$M$6),'טבלת פרמטרים'!$N$6,IF(EXACT(P44,'טבלת פרמטרים'!$M$7),'טבלת פרמטרים'!$N$7,IF(EXACT(P44,'טבלת פרמטרים'!$M$8),'טבלת פרמטרים'!$N$8,IF(EXACT(P44,'טבלת פרמטרים'!$M$9),'טבלת פרמטרים'!$N$9,"")))))))) -> 0 | T44: =IF(EXACT(Q44,'טבלת פרמטרים'!$O$2),'טבלת פרמטרים'!$P$2,IF(EXACT(Q44,'טבלת פרמטרים'!$O$3),'טבלת פרמטרים'!$P$3,IF(EXACT(Q44,'טבלת פרמטרים'!$O$4),'טבלת פרמטרים'!$P$4,IF(EXACT(Q44,'טבלת פרמטרים'!$O$5),'טבלת פרמטרים'!$P$5,IF(EXACT(Q44,'טבלת פרמטרים'!$O$6),'טבלת פרמטרים'!$P$6,IF(EXACT(Q44,'טבלת פרמטרים'!$O$7),'טבלת פרמטרים'!$P$7,"")))))) -> 0
A45: 44 | B45: 43076 | D45: מהלך טיפול | E45: מקרה בטיחות | F45: ללא נפגעים | G45: רב פעמי | H45: תרבות עבודה | I45: עבודת ערב | J45: מאיץ4/מאיץ5 | K45: 3D | L45: תיק רגיל | M45: פרמטר יחיד | N45: חידוד נהל קיים | O45: =IF(ISBLANK(D45),"",IF(D45='טבלת פרמטרים'!$A$9,1,0)+IF(E45='טבלת פרמטרים'!$B$5,2,1)+IF(F45='טבלת פרמטרים'!$C$5,3,IF(F45='טבלת פרמטרים'!$C$4,1,0))+IF(G45='טבלת פרמטרים'!$D$3,2,0)+IF(M45='טבלת פרמטרים'!$J$4,2,IF(M45='טבלת פרמטרים'!$J$3,1,0))+IF(N45='טבלת פרמטרים'!$K$6,3,IF(OR(N45='טבלת פרמטרים'!$K$4,N45='טבלת פרמטרים'!$K$5),2,IF(N45='טבלת פרמטרים'!$K$3,1,0)))) -> 6 | P45: לא נפגע | Q45: לא רלוונטי | R45: =IF(ISNUMBER(T45),T45+O45,O45) -> 6 | S45: =IF(EXACT(P45,'טבלת פרמטרים'!$M$2),'טבלת פרמטרים'!$N$2,IF(EXACT(P45,'טבלת פרמטרים'!$M$3),'טבלת פרמטרים'!$N$3,IF(EXACT(P45,'טבלת פרמטרים'!$M$4),'טבלת פרמטרים'!$N$4,IF(EXACT(P45,'טבלת פרמטרים'!$M$5),'טבלת פרמטרים'!$N$5,IF(EXACT(P45,'טבלת פרמטרים'!$M$6),'טבלת פרמטרים'!$N$6,IF(EXACT(P45,'טבלת פרמטרים'!$M$7),'טבלת פרמטרים'!$N$7,IF(EXACT(P45,'טבלת פרמטרים'!$M$8),'טבלת פרמטרים'!$N$8,IF(EXACT(P45,'טבלת פרמטרים'!$M$9),'טבלת פרמטרים'!$N$9,"")))))))) -> 0 | T45: =IF(EXACT(Q45,'טבלת פרמטרים'!$O$2),'טבלת פרמטרים'!$P$2,IF(EXACT(Q45,'טבלת פרמטרים'!$O$3),'טבלת פרמטרים'!$P$3,IF(EXACT(Q45,'טבלת פרמטרים'!$O$4),'טבלת פרמטרים'!$P$4,IF(EXACT(Q45,'טבלת פרמטרים'!$O$5),'טבלת פרמטרים'!$P$5,IF(EXACT(Q45,'טבלת פרמטרים'!$O$6),'טבלת פרמטרים'!$P$6,IF(EXACT(Q45,'טבלת פרמטרים'!$O$7),'טבלת פרמטרים'!$P$7,"")))))) -> 0
A46: 45 | B46: 43065 | D46: סימולציה | E46: מקרה בטיחות | F46: ללא נפגעים | G46: חד פעמי | H46: תרבות עבודה | I46: עבודת בוקר | J46: סימולציה | K46: SBRT | L46: תיק רגיל | M46: ללא | N46: חידוד נהל קיים | O46: =IF(ISBLANK(D46),"",IF(D46='טבלת פרמטרים'!$A$9,1,0)+IF(E46='טבלת פרמטרים'!$B$5,2,1)+IF(F46='טבלת פרמטרים'!$C$5,3,IF(F46='טבלת פרמטרים'!$C$4,1,0))+IF(G46='טבלת פרמטרים'!$D$3,2,0)+IF(M46='טבלת פרמטרים'!$J$4,2,IF(M46='טבלת פרמטרים'!$J$3,1,0))+IF(N46='טבלת פרמטרים'!$K$6,3,IF(OR(N46='טבלת פרמטרים'!$K$4,N46='טבלת פרמטרים'!$K$5),2,IF(N46='טבלת פרמטרים'!$K$3,1,0)))) -> 2 | P46: לא נפגע | Q46: לא רלוונטי | R46: =IF(ISNUMBER(T46),T46+O46,O46) -> 2 | S46: =IF(EXACT(P46,'טבלת פרמטרים'!$M$2),'טבלת פרמטרים'!$N$2,IF(EXACT(P46,'טבלת פרמטרים'!$M$3),'טבלת פרמטרים'!$N$3,IF(EXACT(P46,'טבלת פרמטרים'!$M$4),'טבלת פרמטרים'!$N$4,IF(EXACT(P46,'טבלת פרמטרים'!$M$5),'טבלת פרמטרים'!$N$5,IF(EXACT(P46,'טבלת פרמטרים'!$M$6),'טבלת פרמטרים'!$N$6,IF(EXACT(P46,'טבלת פרמטרים'!$M$7),'טבלת פרמטרים'!$N$7,IF(EXACT(P46,'טבלת פרמטרים'!$M$8),'טבלת פרמטרים'!$N$8,IF(EXACT(P46,'טבלת פרמטרים'!$M$9),'טבלת פרמטרים'!$N$9,"")))))))) -> 0 | T46: =IF(EXACT(Q46,'טבלת פרמטרים'!$O$2),'טבלת פרמטרים'!$P$2,IF(EXACT(Q46,'טבלת פרמטרים'!$O$3),'טבלת פרמטרים'!$P$3,IF(EXACT(Q46,'טבלת פרמטרים'!$O$4),'טבלת פרמטרים'!$P$4,IF(EXACT(Q46,'טבלת פרמטרים'!$O$5),'טבלת פרמטרים'!$P$5,IF(EXACT(Q46,'טבלת פרמטרים'!$O$6),'טבלת פרמטרים'!$P$6,IF(EXACT(Q46,'טבלת פרמטרים'!$O$7),'טבלת פרמטרים'!$P$7,"")))))) -> 0
A47: 46 | B47: 43116 | D47: לפני טיפול | E47: מנהלי | F47: ללא נפגעים | G47: חד פעמי | H47: תקשורת | I47: עבודת בוקר | J47: מאיץ4/מאיץ5 | K47: IMRT | L47: תיק רגיל | M47: פרמטר יחיד | N47: חידוד נהל קיים | O47: =IF(ISBLANK(D47),"",IF(D47='טבלת פרמטרים'!$A$9,1,0)+IF(E47='טבלת פרמטרים'!$B$5,2,1)+IF(F47='טבלת פרמטרים'!$C$5,3,IF(F47='טבלת פרמטרים'!$C$4,1,0))+IF(G47='טבלת פרמטרים'!$D$3,2,0)+IF(M47='טבלת פרמטרים'!$J$4,2,IF(M47='טבלת פרמטרים'!$J$3,1,0))+IF(N47='טבלת פרמטרים'!$K$6,3,IF(OR(N47='טבלת פרמטרים'!$K$4,N47='טבלת פרמטרים'!$K$5),2,IF(N47='טבלת פרמטרים'!$K$3,1,0)))) -> 3 | P47: לא נפגע | Q47: לא רלוונטי | R47: =IF(ISNUMBER(T47),T47+O47,O47) -> 3 | S47: =IF(EXACT(P47,'טבלת פרמטרים'!$M$2),'טבלת פרמטרים'!$N$2,IF(EXACT(P47,'טבלת פרמטרים'!$M$3),'טבלת פרמטרים'!$N$3,IF(EXACT(P47,'טבלת פרמטרים'!$M$4),'טבלת פרמטרים'!$N$4,IF(EXACT(P47,'טבלת פרמטרים'!$M$5),'טבלת פרמטרים'!$N$5,IF(EXACT(P47,'טבלת פרמטרים'!$M$6),'טבלת פרמטרים'!$N$6,IF(EXACT(P47,'טבלת פרמטרים'!$M$7),'טבלת פרמטרים'!$N$7,IF(EXACT(P47,'טבלת פרמטרים'!$M$8),'טבלת פרמטרים'!$N$8,IF(EXACT(P47,'טבלת פרמטרים'!$M$9),'טבלת פרמטרים'!$N$9,"")))))))) -> 0 | T47: =IF(EXACT(Q47,'טבלת פרמטרים'!$O$2),'טבלת פרמטרים'!$P$2,IF(EXACT(Q47,'טבלת פרמטרים'!$O$3),'טבלת פרמטרים'!$P$3,IF(EXACT(Q47,'טבלת פרמטרים'!$O$4),'טבלת פרמטרים'!$P$4,IF(EXACT(Q47,'טבלת פרמטרים'!$O$5),'טבלת פרמטרים'!$P$5,IF(EXACT(Q47,'טבלת פרמטרים'!$O$6),'טבלת פרמטרים'!$P$6,IF(EXACT(Q47,'טבלת פרמטרים'!$O$7),'טבלת פרמטרים'!$P$7,"")))))) -> 0
A48: 47 | B48: 43070 | D48: מהלך טיפול | E48: נפגע | F48: נפגע יחיד | G48: רב פעמי | H48: תקשורת | I48: עבודת בוקר | J48: מאיץ1/מאיץ2 | K48: IMRT | L48: תיק רגיל | M48: יותר מפרמטר אחד | N48: שינוי נוהל קיים | O48: =IF(ISBLANK(D48),"",IF(D48='טבלת פרמטרים'!$A$9,1,0)+IF(E48='טבלת פרמטרים'!$B$5,2,1)+IF(F48='טבלת פרמטרים'!$C$5,3,IF(F48='טבלת פרמטרים'!$C$4,1,0))+IF(G48='טבלת פרמטרים'!$D$3,2,0)+IF(M48='טבלת פרמטרים'!$J$4,2,IF(M48='טבלת פרמטרים'!$J$3,1,0))+IF(N48='טבלת פרמטרים'!$K$6,3,IF(OR(N48='טבלת פרמטרים'!$K$4,N48='טבלת פרמטרים'!$K$5),2,IF(N48='טבלת פרמטרים'!$K$3,1,0)))) -> 10 | R48: =IF(ISNUMBER(T48),T48+O48,O48) -> 10 | S48: =IF(EXACT(P48,'טבלת פרמטרים'!$M$2),'טבלת פרמטרים'!$N$2,IF(EXACT(P48,'טבלת פרמטרים'!$M$3),'טבלת פרמטרים'!$N$3,IF(EXACT(P48,'טבלת פרמטרים'!$M$4),'טבלת פרמטרים'!$N$4,IF(EXACT(P48,'טבלת פרמטרים'!$M$5),'טבלת פרמטרים'!$N$5,IF(EXACT(P48,'טבלת פרמטרים'!$M$6),'טבלת פרמטרים'!$N$6,IF(EXACT(P48,'טבלת פרמטרים'!$M$7),'טבלת פרמטרים'!$N$7,IF(EXACT(P48,'טבלת פרמטרים'!$M$8),'טבלת פרמטרים'!$N$8,IF(EXACT(P48,'טבלת פרמטרים'!$M$9),'טבלת פרמטרים'!$N$9,"")))))))) | T48: =IF(EXACT(Q48,'טבלת פרמטרים'!$O$2),'טבלת פרמטרים'!$P$2,IF(EXACT(Q48,'טבלת פרמטרים'!$O$3),'טבלת פרמטרים'!$P$3,IF(EXACT(Q48,'טבלת פרמטרים'!$O$4),'טבלת פרמטרים'!$P$4,IF(EXACT(Q48,'טבלת פרמטרים'!$O$5),'טבלת פרמטרים'!$P$5,IF(EXACT(Q48,'טבלת פרמטרים'!$O$6),'טבלת פרמטרים'!$P$6,IF(EXACT(Q48,'טבלת פרמטרים'!$O$7),'טבלת פרמטרים'!$P$7,""))))))
A49: 48 | B49: 43107 | D49: מהלך טיפול | E49: מקרה בטיחות | F49: ללא נפגעים | G49: חד פעמי | H49: תקשורת | I49: עבודת בוקר | J49: מאיץ4/מאיץ5 | K49: 3D | L49: תיק רגיל | M49: יותר מפרמטר אחד | N49: חידוד נהל קיים | O49: =IF(ISBLANK(D49),"",IF(D49='טבלת פרמטרים'!$A$9,1,0)+IF(E49='טבלת פרמטרים'!$B$5,2,1)+IF(F49='טבלת פרמטרים'!$C$5,3,IF(F49='טבלת פרמטרים'!$C$4,1,0))+IF(G49='טבלת פרמטרים'!$D$3,2,0)+IF(M49='טבלת פרמטרים'!$J$4,2,IF(M49='טבלת פרמטרים'!$J$3,1,0))+IF(N49='טבלת פרמטרים'!$K$6,3,IF(OR(N49='טבלת פרמטרים'!$K$4,N49='טבלת פרמטרים'!$K$5),2,IF(N49='טבלת פרמטרים'!$K$3,1,0)))) -> 5 | P49: לא נפגע | Q49: לא רלוונטי | R49: =IF(ISNUMBER(T49),T49+O49,O49) -> 5 | S49: =IF(EXACT(P49,'טבלת פרמטרים'!$M$2),'טבלת פרמטרים'!$N$2,IF(EXACT(P49,'טבלת פרמטרים'!$M$3),'טבלת פרמטרים'!$N$3,IF(EXACT(P49,'טבלת פרמטרים'!$M$4),'טבלת פרמטרים'!$N$4,IF(EXACT(P49,'טבלת פרמטרים'!$M$5),'טבלת פרמטרים'!$N$5,IF(EXACT(P49,'טבלת פרמטרים'!$M$6),'טבלת פרמטרים'!$N$6,IF(EXACT(P49,'טבלת פרמטרים'!$M$7),'טבלת פרמטרים'!$N$7,IF(EXACT(P49,'טבלת פרמטרים'!$M$8),'טבלת פרמטרים'!$N$8,IF(EXACT(P49,'טבלת פרמטרים'!$M$9),'טבלת פרמטרים'!$N$9,"")))))))) -> 0 | T49: =IF(EXACT(Q49,'טבלת פרמטרים'!$O$2),'טבלת פרמטרים'!$P$2,IF(EXACT(Q49,'טבלת פרמטרים'!$O$3),'טבלת פרמטרים'!$P$3,IF(EXACT(Q49,'טבלת פרמטרים'!$O$4),'טבלת פרמטרים'!$P$4,IF(EXACT(Q49,'טבלת פרמטרים'!$O$5),'טבלת פרמטרים'!$P$5,IF(EXACT(Q49,'טבלת פרמטרים'!$O$6),'טבלת פרמטרים'!$P$6,IF(EXACT(Q49,'טבלת פרמטרים'!$O$7),'טבלת פרמטרים'!$P$7,"")))))) -> 0
A50: 49 | B50: 43101 | D50: אחר | E50: מנהלי | F50: ללא נפגעים | G50: חד פעמי | H50: תרבות עבודה | I50: עבודת ערב | J50: מאיץ4/מאיץ5 | K50: סימון קליני | L50: תיק מהיר | M50: ללא | N50: שינוי נוהל קיים | O50: =IF(ISBLANK(D50),"",IF(D50='טבלת פרמטרים'!$A$9,1,0)+IF(E50='טבלת פרמטרים'!$B$5,2,1)+IF(F50='טבלת פרמטרים'!$C$5,3,IF(F50='טבלת פרמטרים'!$C$4,1,0))+IF(G50='טבלת פרמטרים'!$D$3,2,0)+IF(M50='טבלת פרמטרים'!$J$4,2,IF(M50='טבלת פרמטרים'!$J$3,1,0))+IF(N50='טבלת פרמטרים'!$K$6,3,IF(OR(N50='טבלת פרמטרים'!$K$4,N50='טבלת פרמטרים'!$K$5),2,IF(N50='טבלת פרמטרים'!$K$3,1,0)))) -> 3 | P50: לא נפגע | Q50: לא רלוונטי | R50: =IF(ISNUMBER(T50),T50+O50,O50) -> 3 | S50: =IF(EXACT(P50,'טבלת פרמטרים'!$M$2),'טבלת פרמטרים'!$N$2,IF(EXACT(P50,'טבלת פרמטרים'!$M$3),'טבלת פרמטרים'!$N$3,IF(EXACT(P50,'טבלת פרמטרים'!$M$4),'טבלת פרמטרים'!$N$4,IF(EXACT(P50,'טבלת פרמטרים'!$M$5),'טבלת פרמטרים'!$N$5,IF(EXACT(P50,'טבלת פרמטרים'!$M$6),'טבלת פרמטרים'!$N$6,IF(EXACT(P50,'טבלת פרמטרים'!$M$7),'טבלת פרמטרים'!$N$7,IF(EXACT(P50,'טבלת פרמטרים'!$M$8),'טבלת פרמטרים'!$N$8,IF(EXACT(P50,'טבלת פרמטרים'!$M$9),'טבלת פרמטרים'!$N$9,"")))))))) -> 0 | T50: =IF(EXACT(Q50,'טבלת פרמטרים'!$O$2),'טבלת פרמטרים'!$P$2,IF(EXACT(Q50,'טבלת פרמטרים'!$O$3),'טבלת פרמטרים'!$P$3,IF(EXACT(Q50,'טבלת פרמטרים'!$O$4),'טבלת פרמטרים'!$P$4,IF(EXACT(Q50,'טבלת פרמטרים'!$O$5),'טבלת פרמטרים'!$P$5,IF(EXACT(Q50,'טבלת פרמטרים'!$O$6),'טבלת פרמטרים'!$P$6,IF(EXACT(Q50,'טבלת פרמטרים'!$O$7),'טבלת פרמטרים'!$P$7,"")))))) -> 0
A51: 50 | B51: 43090 | D51: מהלך טיפול | E51: נפגע | F51: נפגע יחיד | G51: חד פעמי | H51: תקשורת | I51: עבודת ערב | J51: מאיץ4/מאיץ5 | K51: 3D | L51: תיק רגיל | M51: יותר מפרמטר אחד | N51: שינוי נוהל קיים | O51: =IF(ISBLANK(D51),"",IF(D51='טבלת פרמטרים'!$A$9,1,0)+IF(E51='טבלת פרמטרים'!$B$5,2,1)+IF(F51='טבלת פרמטרים'!$C$5,3,IF(F51='טבלת פרמטרים'!$C$4,1,0))+IF(G51='טבלת פרמטרים'!$D$3,2,0)+IF(M51='טבלת פרמטרים'!$J$4,2,IF(M51='טבלת פרמטרים'!$J$3,1,0))+IF(N51='טבלת פרמטרים'!$K$6,3,IF(OR(N51='טבלת פרמטרים'!$K$4,N51='טבלת פרמטרים'!$K$5),2,IF(N51='טבלת פרמטרים'!$K$3,1,0)))) -> 8 | P51: לא נפגע | Q51: שוני במנה אבסולוטית מהמרשם קטן מ- 5% לכל איבר | R51: =IF(ISNUMBER(T51),T51+O51,O51) -> 9 | S51: =IF(EXACT(P51,'טבלת פרמטרים'!$M$2),'טבלת פרמטרים'!$N$2,IF(EXACT(P51,'טבלת פרמטרים'!$M$3),'טבלת פרמטרים'!$N$3,IF(EXACT(P51,'טבלת פרמטרים'!$M$4),'טבלת פרמטרים'!$N$4,IF(EXACT(P51,'טבלת פרמטרים'!$M$5),'טבלת פרמטרים'!$N$5,IF(EXACT(P51,'טבלת פרמטרים'!$M$6),'טבלת פרמטרים'!$N$6,IF(EXACT(P51,'טבלת פרמטרים'!$M$7),'טבלת פרמטרים'!$N$7,IF(EXACT(P51,'טבלת פרמטרים'!$M$8),'טבלת פרמטרים'!$N$8,IF(EXACT(P51,'טבלת פרמטרים'!$M$9),'טבלת פרמטרים'!$N$9,"")))))))) -> 0 | T51: =IF(EXACT(Q51,'טבלת פרמטרים'!$O$2),'טבלת פרמטרים'!$P$2,IF(EXACT(Q51,'טבלת פרמטרים'!$O$3),'טבלת פרמטרים'!$P$3,IF(EXACT(Q51,'טבלת פרמטרים'!$O$4),'טבלת פרמטרים'!$P$4,IF(EXACT(Q51,'טבלת פרמטרים'!$O$5),'טבלת פרמטרים'!$P$5,IF(EXACT(Q51,'טבלת פרמטרים'!$O$6),'טבלת פרמטרים'!$P$6,IF(EXACT(Q51,'טבלת פרמטרים'!$O$7),'טבלת פרמטרים'!$P$7,"")))))) -> 1
A52: 51 | B52: 43110 | C52: 43110 | D52: סימולציה | E52: מנהלי | F52: ללא נפגעים | G52: חד פעמי | H52: תקשורת | I52: עבודת בוקר | J52: סימולציה | K52: IMRT | L52: תיק רגיל | M52: ללא | N52: ללא שינוי | O52: =IF(ISBLANK(D52),"",IF(D52='טבלת פרמטרים'!$A$9,1,0)+IF(E52='טבלת פרמטרים'!$B$5,2,1)+IF(F52='טבלת פרמטרים'!$C$5,3,IF(F52='טבלת פרמטרים'!$C$4,1,0))+IF(G52='טבלת פרמטרים'!$D$3,2,0)+IF(M52='טבלת פרמטרים'!$J$4,2,IF(M52='טבלת פרמטרים'!$J$3,1,0))+IF(N52='טבלת פרמטרים'!$K$6,3,IF(OR(N52='טבלת פרמטרים'!$K$4,N52='טבלת פרמטרים'!$K$5),2,IF(N52='טבלת פרמטרים'!$K$3,1,0)))) -> 1 | P52: לא נפגע | Q52: לא רלוונטי | R52: =IF(ISNUMBER(T52),T52+O52,O52) -> 1 | S52: =IF(EXACT(P52,'טבלת פרמטרים'!$M$2),'טבלת פרמטרים'!$N$2,IF(EXACT(P52,'טבלת פרמטרים'!$M$3),'טבלת פרמטרים'!$N$3,IF(EXACT(P52,'טבלת פרמטרים'!$M$4),'טבלת פרמטרים'!$N$4,IF(EXACT(P52,'טבלת פרמטרים'!$M$5),'טבלת פרמטרים'!$N$5,IF(EXACT(P52,'טבלת פרמטרים'!$M$6),'טבלת פרמטרים'!$N$6,IF(EXACT(P52,'טבלת פרמטרים'!$M$7),'טבלת פרמטרים'!$N$7,IF(EXACT(P52,'טבלת פרמטרים'!$M$8),'טבלת פרמטרים'!$N$8,IF(EXACT(P52,'טבלת פרמטרים'!$M$9),'טבלת פרמטרים'!$N$9,"")))))))) -> 0 | T52: =IF(EXACT(Q52,'טבלת פרמטרים'!$O$2),'טבלת פרמטרים'!$P$2,IF(EXACT(Q52,'טבלת פרמטרים'!$O$3),'טבלת פרמטרים'!$P$3,IF(EXACT(Q52,'טבלת פרמטרים'!$O$4),'טבלת פרמטרים'!$P$4,IF(EXACT(Q52,'טבלת פרמטרים'!$O$5),'טבלת פרמטרים'!$P$5,IF(EXACT(Q52,'טבלת פרמטרים'!$O$6),'טבלת פרמטרים'!$P$6,IF(EXACT(Q52,'טבלת פרמטרים'!$O$7),'טבלת פרמטרים'!$P$7,"")))))) -> 0
A53: 52 | B53: 43102 | D53: תכנון | E53: מנהלי | F53: ללא נפגעים | G53: חד פעמי | H53: טעות אנוש | I53: עבודת ערב | J53: מאיץ4/מאיץ5 | K53: 3D | L53: תיק דחוף | M53: פרמטר יחיד | N53: ללא שינוי | O53: =IF(ISBLANK(D53),"",IF(D53='טבלת פרמטרים'!$A$9,1,0)+IF(E53='טבלת פרמטרים'!$B$5,2,1)+IF(F53='טבלת פרמטרים'!$C$5,3,IF(F53='טבלת פרמטרים'!$C$4,1,0))+IF(G53='טבלת פרמטרים'!$D$3,2,0)+IF(M53='טבלת פרמטרים'!$J$4,2,IF(M53='טבלת פרמטרים'!$J$3,1,0))+IF(N53='טבלת פרמטרים'!$K$6,3,IF(OR(N53='טבלת פרמטרים'!$K$4,N53='טבלת פרמטרים'!$K$5),2,IF(N53='טבלת פרמטרים'!$K$3,1,0)))) -> 2 | P53: לא נפגע | Q53: לא רלוונטי | R53: =IF(ISNUMBER(T53),T53+O53,O53) -> 2 | S53: =IF(EXACT(P53,'טבלת פרמטרים'!$M$2),'טבלת פרמטרים'!$N$2,IF(EXACT(P53,'טבלת פרמטרים'!$M$3),'טבלת פרמטרים'!$N$3,IF(EXACT(P53,'טבלת פרמטרים'!$M$4),'טבלת פרמטרים'!$N$4,IF(EXACT(P53,'טבלת פרמטרים'!$M$5),'טבלת פרמטרים'!$N$5,IF(EXACT(P53,'טבלת פרמטרים'!$M$6),'טבלת פרמטרים'!$N$6,IF(EXACT(P53,'טבלת פרמטרים'!$M$7),'טבלת פרמטרים'!$N$7,IF(EXACT(P53,'טבלת פרמטרים'!$M$8),'טבלת פרמטרים'!$N$8,IF(EXACT(P53,'טבלת פרמטרים'!$M$9),'טבלת פרמטרים'!$N$9,"")))))))) -> 0 | T53: =IF(EXACT(Q53,'טבלת פרמטרים'!$O$2),'טבלת פרמטרים'!$P$2,IF(EXACT(Q53,'טבלת פרמטרים'!$O$3),'טבלת פרמטרים'!$P$3,IF(EXACT(Q53,'טבלת פרמטרים'!$O$4),'טבלת פרמטרים'!$P$4,IF(EXACT(Q53,'טבלת פרמטרים'!$O$5),'טבלת פרמטרים'!$P$5,IF(EXACT(Q53,'טבלת פרמטרים'!$O$6),'טבלת פרמטרים'!$P$6,IF(EXACT(Q53,'טבלת פרמטרים'!$O$7),'טבלת פרמטרים'!$P$7,"")))))) -> 0
A54: 53 | B54: 42932 | D54: מהלך טיפול | E54: מקרה בטיחות | F54: ללא נפגעים | G54: חד פעמי | H54: תקלה טכנית | I54: עבודת בוקר | J54: מאיץ1/מאיץ2 | K54: SBRT | L54: תיק רגיל | M54: ללא | N54: נהל חדש | O54: =IF(ISBLANK(D54),"",IF(D54='טבלת פרמטרים'!$A$9,1,0)+IF(E54='טבלת פרמטרים'!$B$5,2,1)+IF(F54='טבלת פרמטרים'!$C$5,3,IF(F54='טבלת פרמטרים'!$C$4,1,0))+IF(G54='טבלת פרמטרים'!$D$3,2,0)+IF(M54='טבלת פרמטרים'!$J$4,2,IF(M54='טבלת פרמטרים'!$J$3,1,0))+IF(N54='טבלת פרמטרים'!$K$6,3,IF(OR(N54='טבלת פרמטרים'!$K$4,N54='טבלת פרמטרים'!$K$5),2,IF(N54='טבלת פרמטרים'!$K$3,1,0)))) -> 4 | P54: לא נפגע | Q54: לא רלוונטי | R54: =IF(ISNUMBER(T54),T54+O54,O54) -> 4 | S54: =IF(EXACT(P54,'טבלת פרמטרים'!$M$2),'טבלת פרמטרים'!$N$2,IF(EXACT(P54,'טבלת פרמטרים'!$M$3),'טבלת פרמטרים'!$N$3,IF(EXACT(P54,'טבלת פרמטרים'!$M$4),'טבלת פרמטרים'!$N$4,IF(EXACT(P54,'טבלת פרמטרים'!$M$5),'טבלת פרמטרים'!$N$5,IF(EXACT(P54,'טבלת פרמטרים'!$M$6),'טבלת פרמטרים'!$N$6,IF(EXACT(P54,'טבלת פרמטרים'!$M$7),'טבלת פרמטרים'!$N$7,IF(EXACT(P54,'טבלת פרמטרים'!$M$8),'טבלת פרמטרים'!$N$8,IF(EXACT(P54,'טבלת פרמטרים'!$M$9),'טבלת פרמטרים'!$N$9,"")))))))) -> 0 | T54: =IF(EXACT(Q54,'טבלת פרמטרים'!$O$2),'טבלת פרמטרים'!$P$2,IF(EXACT(Q54,'טבלת פרמטרים'!$O$3),'טבלת פרמטרים'!$P$3,IF(EXACT(Q54,'טבלת פרמטרים'!$O$4),'טבלת פרמטרים'!$P$4,IF(EXACT(Q54,'טבלת פרמטרים'!$O$5),'טבלת פרמטרים'!$P$5,IF(EXACT(Q54,'טבלת פרמטרים'!$O$6),'טבלת פרמטרים'!$P$6,IF(EXACT(Q54,'טבלת פרמטרים'!$O$7),'טבלת פרמטרים'!$P$7,"")))))) -> 0
A55: 54 | B55: 42904 | D55: מעקב | E55: נפגע | F55: נפגע יחיד | G55: רב פעמי | H55: תרבות עבודה | I55: עבודת בוקר | J55: מאיץ4/מאיץ5 | K55: IMRT | L55: תיק רגיל | M55: ללא | N55: חידוד נהל קיים | O55: =IF(ISBLANK(D55),"",IF(D55='טבלת פרמטרים'!$A$9,1,0)+IF(E55='טבלת פרמטרים'!$B$5,2,1)+IF(F55='טבלת פרמטרים'!$C$5,3,IF(F55='טבלת פרמטרים'!$C$4,1,0))+IF(G55='טבלת פרמטרים'!$D$3,2,0)+IF(M55='טבלת פרמטרים'!$J$4,2,IF(M55='טבלת פרמטרים'!$J$3,1,0))+IF(N55='טבלת פרמטרים'!$K$6,3,IF(OR(N55='טבלת פרמטרים'!$K$4,N55='טבלת פרמטרים'!$K$5),2,IF(N55='טבלת פרמטרים'!$K$3,1,0)))) -> 6 | P55: לא נפגע | Q55: שוני במנה אבסולוטית מהמרשם בין 10% ל- 25% לכל איבר | R55: =IF(ISNUMBER(T55),T55+O55,O55) -> 12 | S55: =IF(EXACT(P55,'טבלת פרמטרים'!$M$2),'טבלת פרמטרים'!$N$2,IF(EXACT(P55,'טבלת פרמטרים'!$M$3),'טבלת פרמטרים'!$N$3,IF(EXACT(P55,'טבלת פרמטרים'!$M$4),'טבלת פרמטרים'!$N$4,IF(EXACT(P55,'טבלת פרמטרים'!$M$5),'טבלת פרמטרים'!$N$5,IF(EXACT(P55,'טבלת פרמטרים'!$M$6),'טבלת פרמטרים'!$N$6,IF(EXACT(P55,'טבלת פרמטרים'!$M$7),'טבלת פרמטרים'!$N$7,IF(EXACT(P55,'טבלת פרמטרים'!$M$8),'טבלת פרמטרים'!$N$8,IF(EXACT(P55,'טבלת פרמטרים'!$M$9),'טבלת פרמטרים'!$N$9,"")))))))) -> 0 | T55: =IF(EXACT(Q55,'טבלת פרמטרים'!$O$2),'טבלת פרמטרים'!$P$2,IF(EXACT(Q55,'טבלת פרמטרים'!$O$3),'טבלת פרמטרים'!$P$3,IF(EXACT(Q55,'טבלת פרמטרים'!$O$4),'טבלת פרמטרים'!$P$4,IF(EXACT(Q55,'טבלת פרמטרים'!$O$5),'טבלת פרמטרים'!$P$5,IF(EXACT(Q55,'טבלת פרמטרים'!$O$6),'טבלת פרמטרים'!$P$6,IF(EXACT(Q55,'טבלת פרמטרים'!$O$7),'טבלת פרמטרים'!$P$7,"")))))) -> 6
A56: 55 | B56: 43107 | C56: 43107 | D56: מרשם | E56: מקרה בטיחות | F56: ללא נפגעים | G56: חד פעמי | H56: תרבות עבודה | I56: עבודת בוקר | J56: מאיץ1/מאיץ2 | K56: SBRT | L56: תיק רגיל | M56: ללא | N56: חידוד נהל קיים | O56: =IF(ISBLANK(D56),"",IF(D56='טבלת פרמטרים'!$A$9,1,0)+IF(E56='טבלת פרמטרים'!$B$5,2,1)+IF(F56='טבלת פרמטרים'!$C$5,3,IF(F56='טבלת פרמטרים'!$C$4,1,0))+IF(G56='טבלת פרמטרים'!$D$3,2,0)+IF(M56='טבלת פרמטרים'!$J$4,2,IF(M56='טבלת פרמטרים'!$J$3,1,0))+IF(N56='טבלת פרמטרים'!$K$6,3,IF(OR(N56='טבלת פרמטרים'!$K$4,N56='טבלת פרמטרים'!$K$5),2,IF(N56='טבלת פרמטרים'!$K$3,1,0)))) -> 2 | R56: =IF(ISNUMBER(T56),T56+O56,O56) -> 2 | S56: =IF(EXACT(P56,'טבלת פרמטרים'!$M$2),'טבלת פרמטרים'!$N$2,IF(EXACT(P56,'טבלת פרמטרים'!$M$3),'טבלת פרמטרים'!$N$3,IF(EXACT(P56,'טבלת פרמטרים'!$M$4),'טבלת פרמטרים'!$N$4,IF(EXACT(P56,'טבלת פרמטרים'!$M$5),'טבלת פרמטרים'!$N$5,IF(EXACT(P56,'טבלת פרמטרים'!$M$6),'טבלת פרמטרים'!$N$6,IF(EXACT(P56,'טבלת פרמטרים'!$M$7),'טבלת פרמטרים'!$N$7,IF(EXACT(P56,'טבלת פרמטרים'!$M$8),'טבלת פרמטרים'!$N$8,IF(EXACT(P56,'טבלת פרמטרים'!$M$9),'טבלת פרמטרים'!$N$9,"")))))))) | T56: =IF(EXACT(Q56,'טבלת פרמטרים'!$O$2),'טבלת פרמטרים'!$P$2,IF(EXACT(Q56,'טבלת פרמטרים'!$O$3),'טבלת פרמטרים'!$P$3,IF(EXACT(Q56,'טבלת פרמטרים'!$O$4),'טבלת פרמטרים'!$P$4,IF(EXACT(Q56,'טבלת פרמטרים'!$O$5),'טבלת פרמטרים'!$P$5,IF(EXACT(Q56,'טבלת פרמטרים'!$O$6),'טבלת פרמטרים'!$P$6,IF(EXACT(Q56,'טבלת פרמטרים'!$O$7),'טבלת פרמטרים'!$P$7,""))))))
A57: 56 | B57: 43124 | C57: 43124 | D57: סימולציה | E57: מקרה בטיחות | F57: ללא נפגעים | G57: חד פעמי | H57: טעות אנוש | I57: עבודת בוקר | J57: סימולציה | K57: 3D | L57: תיק רגיל | M57: ללא | N57: חידוד נהל קיים | O57: =IF(ISBLANK(D57),"",IF(D57='טבלת פרמטרים'!$A$9,1,0)+IF(E57='טבלת פרמטרים'!$B$5,2,1)+IF(F57='טבלת פרמטרים'!$C$5,3,IF(F57='טבלת פרמטרים'!$C$4,1,0))+IF(G57='טבלת פרמטרים'!$D$3,2,0)+IF(M57='טבלת פרמטרים'!$J$4,2,IF(M57='טבלת פרמטרים'!$J$3,1,0))+IF(N57='טבלת פרמטרים'!$K$6,3,IF(OR(N57='טבלת פרמטרים'!$K$4,N57='טבלת פרמטרים'!$K$5),2,IF(N57='טבלת פרמטרים'!$K$3,1,0)))) -> 2 | R57: =IF(ISNUMBER(T57),T57+O57,O57) -> 2 | S57: =IF(EXACT(P57,'טבלת פרמטרים'!$M$2),'טבלת פרמטרים'!$N$2,IF(EXACT(P57,'טבלת פרמטרים'!$M$3),'טבלת פרמטרים'!$N$3,IF(EXACT(P57,'טבלת פרמטרים'!$M$4),'טבלת פרמטרים'!$N$4,IF(EXACT(P57,'טבלת פרמטרים'!$M$5),'טבלת פרמטרים'!$N$5,IF(EXACT(P57,'טבלת פרמטרים'!$M$6),'טבלת פרמטרים'!$N$6,IF(EXACT(P57,'טבלת פרמטרים'!$M$7),'טבלת פרמטרים'!$N$7,IF(EXACT(P57,'טבלת פרמטרים'!$M$8),'טבלת פרמטרים'!$N$8,IF(EXACT(P57,'טבלת פרמטרים'!$M$9),'טבלת פרמטרים'!$N$9,"")))))))) | T57: =IF(EXACT(Q57,'טבלת פרמטרים'!$O$2),'טבלת פרמטרים'!$P$2,IF(EXACT(Q57,'טבלת פרמטרים'!$O$3),'טבלת פרמטרים'!$P$3,IF(EXACT(Q57,'טבלת פרמטרים'!$O$4),'טבלת פרמטרים'!$P$4,IF(EXACT(Q57,'טבלת פרמטרים'!$O$5),'טבלת פרמטרים'!$P$5,IF(EXACT(Q57,'טבלת פרמטרים'!$O$6),'טבלת פרמטרים'!$P$6,IF(EXACT(Q57,'טבלת פרמטרים'!$O$7),'טבלת פרמטרים'!$P$7,""))))))
A58: 57 | B58: 43156 | C58: 43156 | D58: מהלך טיפול | E58: נפגע | F58: נפגע יחיד | G58: חד פעמי | H58: טעות אנוש | I58: עבודת בוקר | J58: מאיץ4/מאיץ5 | K58: 3D | L58: תיק רגיל | M58: ללא | N58: נהל חדש | O58: =IF(ISBLANK(D58),"",IF(D58='טבלת פרמטרים'!$A$9,1,0)+IF(E58='טבלת פרמטרים'!$B$5,2,1)+IF(F58='טבלת פרמטרים'!$C$5,3,IF(F58='טבלת פרמטרים'!$C$4,1,0))+IF(G58='טבלת פרמטרים'!$D$3,2,0)+IF(M58='טבלת פרמטרים'!$J$4,2,IF(M58='טבלת פרמטרים'!$J$3,1,0))+IF(N58='טבלת פרמטרים'!$K$6,3,IF(OR(N58='טבלת פרמטרים'!$K$4,N58='טבלת פרמטרים'!$K$5),2,IF(N58='טבלת פרמטרים'!$K$3,1,0)))) -> 6 | R58: =IF(ISNUMBER(T58),T58+O58,O58) -> 6 | S58: =IF(EXACT(P58,'טבלת פרמטרים'!$M$2),'טבלת פרמטרים'!$N$2,IF(EXACT(P58,'טבלת פרמטרים'!$M$3),'טבלת פרמטרים'!$N$3,IF(EXACT(P58,'טבלת פרמטרים'!$M$4),'טבלת פרמטרים'!$N$4,IF(EXACT(P58,'טבלת פרמטרים'!$M$5),'טבלת פרמטרים'!$N$5,IF(EXACT(P58,'טבלת פרמטרים'!$M$6),'טבלת פרמטרים'!$N$6,IF(EXACT(P58,'טבלת פרמטרים'!$M$7),'טבלת פרמטרים'!$N$7,IF(EXACT(P58,'טבלת פרמטרים'!$M$8),'טבלת פרמטרים'!$N$8,IF(EXACT(P58,'טבלת פרמטרים'!$M$9),'טבלת פרמטרים'!$N$9,"")))))))) | T58: =IF(EXACT(Q58,'טבלת פרמטרים'!$O$2),'טבלת פרמטרים'!$P$2,IF(EXACT(Q58,'טבלת פרמטרים'!$O$3),'טבלת פרמטרים'!$P$3,IF(EXACT(Q58,'טבלת פרמטרים'!$O$4),'טבלת פרמטרים'!$P$4,IF(EXACT(Q58,'טבלת פרמטרים'!$O$5),'טבלת פרמטרים'!$P$5,IF(EXACT(Q58,'טבלת פרמטרים'!$O$6),'טבלת פרמטרים'!$P$6,IF(EXACT(Q58,'טבלת פרמטרים'!$O$7),'טבלת פרמטרים'!$P$7,""))))))
A59: 58 | B59: 43163 | C59: 43163 | D59: תכנון | E59: מקרה בטיחות | F59: ללא נפגעים | G59: רב פעמי | H59: תרבות עבודה | I59: עבודת בוקר | J59: מאיץ4/מאיץ5 | K59: אחר | L59: תיק רגיל | M59: יותר מפרמטר אחד | N59: חידוד נהל קיים | O59: =IF(ISBLANK(D59),"",IF(D59='טבלת פרמטרים'!$A$9,1,0)+IF(E59='טבלת פרמטרים'!$B$5,2,1)+IF(F59='טבלת פרמטרים'!$C$5,3,IF(F59='טבלת פרמטרים'!$C$4,1,0))+IF(G59='טבלת פרמטרים'!$D$3,2,0)+IF(M59='טבלת פרמטרים'!$J$4,2,IF(M59='טבלת פרמטרים'!$J$3,1,0))+IF(N59='טבלת פרמטרים'!$K$6,3,IF(OR(N59='טבלת פרמטרים'!$K$4,N59='טבלת פרמטרים'!$K$5),2,IF(N59='טבלת פרמטרים'!$K$3,1,0)))) -> 6 | P59: לא נפגע | Q59: לא רלוונטי | R59: =IF(ISNUMBER(T59),T59+O59,O59) -> 6 | S59: =IF(EXACT(P59,'טבלת פרמטרים'!$M$2),'טבלת פרמטרים'!$N$2,IF(EXACT(P59,'טבלת פרמטרים'!$M$3),'טבלת פרמטרים'!$N$3,IF(EXACT(P59,'טבלת פרמטרים'!$M$4),'טבלת פרמטרים'!$N$4,IF(EXACT(P59,'טבלת פרמטרים'!$M$5),'טבלת פרמטרים'!$N$5,IF(EXACT(P59,'טבלת פרמטרים'!$M$6),'טבלת פרמטרים'!$N$6,IF(EXACT(P59,'טבלת פרמטרים'!$M$7),'טבלת פרמטרים'!$N$7,IF(EXACT(P59,'טבלת פרמטרים'!$M$8),'טבלת פרמטרים'!$N$8,IF(EXACT(P59,'טבלת פרמטרים'!$M$9),'טבלת פרמטרים'!$N$9,"")))))))) -> 0 | T59: =IF(EXACT(Q59,'טבלת פרמטרים'!$O$2),'טבלת פרמטרים'!$P$2,IF(EXACT(Q59,'טבלת פרמטרים'!$O$3),'טבלת פרמטרים'!$P$3,IF(EXACT(Q59,'טבלת פרמטרים'!$O$4),'טבלת פרמטרים'!$P$4,IF(EXACT(Q59,'טבלת פרמטרים'!$O$5),'טבלת פרמטרים'!$P$5,IF(EXACT(Q59,'טבלת פרמטרים'!$O$6),'טבלת פרמטרים'!$P$6,IF(EXACT(Q59,'טבלת פרמטרים'!$O$7),'טבלת פרמטרים'!$P$7,"")))))) -> 0
A60: 59 | B60: 43144 | C60: 43149 | D60: מעקב | E60: מקרה בטיחות | F60: ללא נפגעים | G60: רב פעמי | H60: אחר | I60: עבודת בוקר | J60: מאיץ1/מאיץ2 | K60: 3D | L60: תיק מהיר | M60: פרמטר יחיד | N60: נהל חדש | O60: =IF(ISBLANK(D60),"",IF(D60='טבלת פרמטרים'!$A$9,1,0)+IF(E60='טבלת פרמטרים'!$B$5,2,1)+IF(F60='טבלת פרמטרים'!$C$5,3,IF(F60='טבלת פרמטרים'!$C$4,1,0))+IF(G60='טבלת פרמטרים'!$D$3,2,0)+IF(M60='טבלת פרמטרים'!$J$4,2,IF(M60='טבלת פרמטרים'!$J$3,1,0))+IF(N60='טבלת פרמטרים'!$K$6,3,IF(OR(N60='טבלת פרמטרים'!$K$4,N60='טבלת פרמטרים'!$K$5),2,IF(N60='טבלת פרמטרים'!$K$3,1,0)))) -> 6 | P60: לא נפגע | Q60: לא רלוונטי | R60: =IF(ISNUMBER(T60),T60+O60,O60) -> 6 | S60: =IF(EXACT(P60,'טבלת פרמטרים'!$M$2),'טבלת פרמטרים'!$N$2,IF(EXACT(P60,'טבלת פרמטרים'!$M$3),'טבלת פרמטרים'!$N$3,IF(EXACT(P60,'טבלת פרמטרים'!$M$4),'טבלת פרמטרים'!$N$4,IF(EXACT(P60,'טבלת פרמטרים'!$M$5),'טבלת פרמטרים'!$N$5,IF(EXACT(P60,'טבלת פרמטרים'!$M$6),'טבלת פרמטרים'!$N$6,IF(EXACT(P60,'טבלת פרמטרים'!$M$7),'טבלת פרמטרים'!$N$7,IF(EXACT(P60,'טבלת פרמטרים'!$M$8),'טבלת פרמטרים'!$N$8,IF(EXACT(P60,'טבלת פרמטרים'!$M$9),'טבלת פרמטרים'!$N$9,"")))))))) -> 0 | T60: =IF(EXACT(Q60,'טבלת פרמטרים'!$O$2),'טבלת פרמטרים'!$P$2,IF(EXACT(Q60,'טבלת פרמטרים'!$O$3),'טבלת פרמטרים'!$P$3,IF(EXACT(Q60,'טבלת פרמטרים'!$O$4),'טבלת פרמטרים'!$P$4,IF(EXACT(Q60,'טבלת פרמטרים'!$O$5),'טבלת פרמטרים'!$P$5,IF(EXACT(Q60,'טבלת פרמטרים'!$O$6),'טבלת פרמטרים'!$P$6,IF(EXACT(Q60,'טבלת פרמטרים'!$O$7),'טבלת פרמטרים'!$P$7,"")))))) -> 0
A61: 60 | B61: 43143 | C61: 43144 | D61: מהלך טיפול | E61: מנהלי | F61: נפגע יחיד | G61: חד פעמי | H61: טעות אנוש | I61: עבודת בוקר | J61: מאיץ4/מאיץ5 | K61: 3D | L61: תיק דחוף | M61: ללא | N61: חידוד נהל קיים | O61: =IF(ISBLANK(D61),"",IF(D61='טבלת פרמטרים'!$A$9,1,0)+IF(E61='טבלת פרמטרים'!$B$5,2,1)+IF(F61='טבלת פרמטרים'!$C$5,3,IF(F61='טבלת פרמטרים'!$C$4,1,0))+IF(G61='טבלת פרמטרים'!$D$3,2,0)+IF(M61='טבלת פרמטרים'!$J$4,2,IF(M61='טבלת פרמטרים'!$J$3,1,0))+IF(N61='טבלת פרמטרים'!$K$6,3,IF(OR(N61='טבלת פרמטרים'!$K$4,N61='טבלת פרמטרים'!$K$5),2,IF(N61='טבלת פרמטרים'!$K$3,1,0)))) -> 4 | P61: לא נפגע | Q61: שוני במנה אבסולוטית מהמרשם קטן מ- 5% לכל איבר | R61: =IF(ISNUMBER(T61),T61+O61,O61) -> 5 | S61: =IF(EXACT(P61,'טבלת פרמטרים'!$M$2),'טבלת פרמטרים'!$N$2,IF(EXACT(P61,'טבלת פרמטרים'!$M$3),'טבלת פרמטרים'!$N$3,IF(EXACT(P61,'טבלת פרמטרים'!$M$4),'טבלת פרמטרים'!$N$4,IF(EXACT(P61,'טבלת פרמטרים'!$M$5),'טבלת פרמטרים'!$N$5,IF(EXACT(P61,'טבלת פרמטרים'!$M$6),'טבלת פרמטרים'!$N$6,IF(EXACT(P61,'טבלת פרמטרים'!$M$7),'טבלת פרמטרים'!$N$7,IF(EXACT(P61,'טבלת פרמטרים'!$M$8),'טבלת פרמטרים'!$N$8,IF(EXACT(P61,'טבלת פרמטרים'!$M$9),'טבלת פרמטרים'!$N$9,"")))))))) -> 0 | T61: =IF(EXACT(Q61,'טבלת פרמטרים'!$O$2),'טבלת פרמטרים'!$P$2,IF(EXACT(Q61,'טבלת פרמטרים'!$O$3),'טבלת פרמטרים'!$P$3,IF(EXACT(Q61,'טבלת פרמטרים'!$O$4),'טבלת פרמטרים'!$P$4,IF(EXACT(Q61,'טבלת פרמטרים'!$O$5),'טבלת פרמטרים'!$P$5,IF(EXACT(Q61,'טבלת פרמטרים'!$O$6),'טבלת פרמטרים'!$P$6,IF(EXACT(Q61,'טבלת פרמטרים'!$O$7),'טבלת פרמטרים'!$P$7,"")))))) -> 1
A62: 61 | B62: 43145 | C62: 43145 | D62: מהלך טיפול | E62: כמעט נפגע | F62: ללא נפגעים | G62: חד פעמי | H62: תקלה טכנית | I62: עבודת בוקר | J62: ברכיתרפיה | K62: ברכיתרפיה | L62: תיק רגיל | M62: ללא | N62: ללא שינוי | O62: =IF(ISBLANK(D62),"",IF(D62='טבלת פרמטרים'!$A$9,1,0)+IF(E62='טבלת פרמטרים'!$B$5,2,1)+IF(F62='טבלת פרמטרים'!$C$5,3,IF(F62='טבלת פרמטרים'!$C$4,1,0))+IF(G62='טבלת פרמטרים'!$D$3,2,0)+IF(M62='טבלת פרמטרים'!$J$4,2,IF(M62='טבלת פרמטרים'!$J$3,1,0))+IF(N62='טבלת פרמטרים'!$K$6,3,IF(OR(N62='טבלת פרמטרים'!$K$4,N62='טבלת פרמטרים'!$K$5),2,IF(N62='טבלת פרמטרים'!$K$3,1,0)))) -> 2 | P62: לא נפגע | Q62: לא רלוונטי | R62: =IF(ISNUMBER(T62),T62+O62,O62) -> 2 | S62: =IF(EXACT(P62,'טבלת פרמטרים'!$M$2),'טבלת פרמטרים'!$N$2,IF(EXACT(P62,'טבלת פרמטרים'!$M$3),'טבלת פרמטרים'!$N$3,IF(EXACT(P62,'טבלת פרמטרים'!$M$4),'טבלת פרמטרים'!$N$4,IF(EXACT(P62,'טבלת פרמטרים'!$M$5),'טבלת פרמטרים'!$N$5,IF(EXACT(P62,'טבלת פרמטרים'!$M$6),'טבלת פרמטרים'!$N$6,IF(EXACT(P62,'טבלת פרמטרים'!$M$7),'טבלת פרמטרים'!$N$7,IF(EXACT(P62,'טבלת פרמטרים'!$M$8),'טבלת פרמטרים'!$N$8,IF(EXACT(P62,'טבלת פרמטרים'!$M$9),'טבלת פרמטרים'!$N$9,"")))))))) -> 0 | T62: =IF(EXACT(Q62,'טבלת פרמטרים'!$O$2),'טבלת פרמטרים'!$P$2,IF(EXACT(Q62,'טבלת פרמטרים'!$O$3),'טבלת פרמטרים'!$P$3,IF(EXACT(Q62,'טבלת פרמטרים'!$O$4),'טבלת פרמטרים'!$P$4,IF(EXACT(Q62,'טבלת פרמטרים'!$O$5),'טבלת פרמטרים'!$P$5,IF(EXACT(Q62,'טבלת פרמטרים'!$O$6),'טבלת פרמטרים'!$P$6,IF(EXACT(Q62,'טבלת פרמטרים'!$O$7),'טבלת פרמטרים'!$P$7,"")))))) -> 0
A63: 62 | B63: 43143 | C63: 43143 | D63: מהלך טיפול | E63: נפגע | F63: נפגע יחיד | G63: חד פעמי | H63: טעות אנוש | I63: עבודת בוקר | J63: טיפול מגע | K63: טיפול מגע | L63: תיק רגיל | M63: פרמטר יחיד | N63: המשך חקירת ארוע | O63: =IF(ISBLANK(D63),"",IF(D63='טבלת פרמטרים'!$A$9,1,0)+IF(E63='טבלת פרמטרים'!$B$5,2,1)+IF(F63='טבלת פרמטרים'!$C$5,3,IF(F63='טבלת פרמטרים'!$C$4,1,0))+IF(G63='טבלת פרמטרים'!$D$3,2,0)+IF(M63='טבלת פרמטרים'!$J$4,2,IF(M63='טבלת פרמטרים'!$J$3,1,0))+IF(N63='טבלת פרמטרים'!$K$6,3,IF(OR(N63='טבלת פרמטרים'!$K$4,N63='טבלת פרמטרים'!$K$5),2,IF(N63='טבלת פרמטרים'!$K$3,1,0)))) -> 8 | P63: לא נפגע | Q63: שוני במנה אבסולוטית מהמרשם קטן מ- 5% לכל איבר | R63: =IF(ISNUMBER(T63),T63+O63,O63) -> 9 | S63: =IF(EXACT(P63,'טבלת פרמטרים'!$M$2),'טבלת פרמטרים'!$N$2,IF(EXACT(P63,'טבלת פרמטרים'!$M$3),'טבלת פרמטרים'!$N$3,IF(EXACT(P63,'טבלת פרמטרים'!$M$4),'טבלת פרמטרים'!$N$4,IF(EXACT(P63,'טבלת פרמטרים'!$M$5),'טבלת פרמטרים'!$N$5,IF(EXACT(P63,'טבלת פרמטרים'!$M$6),'טבלת פרמטרים'!$N$6,IF(EXACT(P63,'טבלת פרמטרים'!$M$7),'טבלת פרמטרים'!$N$7,IF(EXACT(P63,'טבלת פרמטרים'!$M$8),'טבלת פרמטרים'!$N$8,IF(EXACT(P63,'טבלת פרמטרים'!$M$9),'טבלת פרמטרים'!$N$9,"")))))))) -> 0 | T63: =IF(EXACT(Q63,'טבלת פרמטרים'!$O$2),'טבלת פרמטרים'!$P$2,IF(EXACT(Q63,'טבלת פרמטרים'!$O$3),'טבלת פרמטרים'!$P$3,IF(EXACT(Q63,'טבלת פרמטרים'!$O$4),'טבלת פרמטרים'!$P$4,IF(EXACT(Q63,'טבלת פרמטרים'!$O$5),'טבלת פרמטרים'!$P$5,IF(EXACT(Q63,'טבלת פרמטרים'!$O$6),'טבלת פרמטרים'!$P$6,IF(EXACT(Q63,'טבלת פרמטרים'!$O$7),'טבלת פרמטרים'!$P$7,"")))))) -> 1
A64: 63 | B64: 43158 | C64: 43158 | D64: לפני טיפול | E64: מקרה בטיחות | F64: ללא נפגעים | G64: חד פעמי | H64: תרבות עבודה | I64: עבודת בוקר | J64: מאיץ4/מאיץ5 | K64: 3D | L64: תיק רגיל | M64: ללא | N64: חידוד נהל קיים | O64: =IF(ISBLANK(D64),"",IF(D64='טבלת פרמטרים'!$A$9,1,0)+IF(E64='טבלת פרמטרים'!$B$5,2,1)+IF(F64='טבלת פרמטרים'!$C$5,3,IF(F64='טבלת פרמטרים'!$C$4,1,0))+IF(G64='טבלת פרמטרים'!$D$3,2,0)+IF(M64='טבלת פרמטרים'!$J$4,2,IF(M64='טבלת פרמטרים'!$J$3,1,0))+IF(N64='טבלת פרמטרים'!$K$6,3,IF(OR(N64='טבלת פרמטרים'!$K$4,N64='טבלת פרמטרים'!$K$5),2,IF(N64='טבלת פרמטרים'!$K$3,1,0)))) -> 2 | P64: לא נפגע | Q64: לא רלוונטי | R64: =IF(ISNUMBER(T64),T64+O64,O64) -> 2 | S64: =IF(EXACT(P64,'טבלת פרמטרים'!$M$2),'טבלת פרמטרים'!$N$2,IF(EXACT(P64,'טבלת פרמטרים'!$M$3),'טבלת פרמטרים'!$N$3,IF(EXACT(P64,'טבלת פרמטרים'!$M$4),'טבלת פרמטרים'!$N$4,IF(EXACT(P64,'טבלת פרמטרים'!$M$5),'טבלת פרמטרים'!$N$5,IF(EXACT(P64,'טבלת פרמטרים'!$M$6),'טבלת פרמטרים'!$N$6,IF(EXACT(P64,'טבלת פרמטרים'!$M$7),'טבלת פרמטרים'!$N$7,IF(EXACT(P64,'טבלת פרמטרים'!$M$8),'טבלת פרמטרים'!$N$8,IF(EXACT(P64,'טבלת פרמטרים'!$M$9),'טבלת פרמטרים'!$N$9,"")))))))) -> 0 | T64: =IF(EXACT(Q64,'טבלת פרמטרים'!$O$2),'טבלת פרמטרים'!$P$2,IF(EXACT(Q64,'טבלת פרמטרים'!$O$3),'טבלת פרמטרים'!$P$3,IF(EXACT(Q64,'טבלת פרמטרים'!$O$4),'טבלת פרמטרים'!$P$4,IF(EXACT(Q64,'טבלת פרמטרים'!$O$5),'טבלת פרמטרים'!$P$5,IF(EXACT(Q64,'טבלת פרמטרים'!$O$6),'טבלת פרמטרים'!$P$6,IF(EXACT(Q64,'טבלת פרמטרים'!$O$7),'טבלת פרמטרים'!$P$7,"")))))) -> 0
A65: 64 | B65: 43194 | C65: 43194 | D65: סימולציה | E65: מקרה בטיחות | F65: ללא נפגעים | G65: חד פעמי | H65: תקשורת | I65: עבודת בוקר | J65: לא ישים | K65: SBRT | L65: תיק רגיל | M65: ללא | N65: חידוד נהל קיים | O65: =IF(ISBLANK(D65),"",IF(D65='טבלת פרמטרים'!$A$9,1,0)+IF(E65='טבלת פרמטרים'!$B$5,2,1)+IF(F65='טבלת פרמטרים'!$C$5,3,IF(F65='טבלת פרמטרים'!$C$4,1,0))+IF(G65='טבלת פרמטרים'!$D$3,2,0)+IF(M65='טבלת פרמטרים'!$J$4,2,IF(M65='טבלת פרמטרים'!$J$3,1,0))+IF(N65='טבלת פרמטרים'!$K$6,3,IF(OR(N65='טבלת פרמטרים'!$K$4,N65='טבלת פרמטרים'!$K$5),2,IF(N65='טבלת פרמטרים'!$K$3,1,0)))) -> 2 | P65: לא נפגע | Q65: לא רלוונטי | R65: =IF(ISNUMBER(T65),T65+O65,O65) -> 2 | S65: =IF(EXACT(P65,'טבלת פרמטרים'!$M$2),'טבלת פרמטרים'!$N$2,IF(EXACT(P65,'טבלת פרמטרים'!$M$3),'טבלת פרמטרים'!$N$3,IF(EXACT(P65,'טבלת פרמטרים'!$M$4),'טבלת פרמטרים'!$N$4,IF(EXACT(P65,'טבלת פרמטרים'!$M$5),'טבלת פרמטרים'!$N$5,IF(EXACT(P65,'טבלת פרמטרים'!$M$6),'טבלת פרמטרים'!$N$6,IF(EXACT(P65,'טבלת פרמטרים'!$M$7),'טבלת פרמטרים'!$N$7,IF(EXACT(P65,'טבלת פרמטרים'!$M$8),'טבלת פרמטרים'!$N$8,IF(EXACT(P65,'טבלת פרמטרים'!$M$9),'טבלת פרמטרים'!$N$9,"")))))))) -> 0 | T65: =IF(EXACT(Q65,'טבלת פרמטרים'!$O$2),'טבלת פרמטרים'!$P$2,IF(EXACT(Q65,'טבלת פרמטרים'!$O$3),'טבלת פרמטרים'!$P$3,IF(EXACT(Q65,'טבלת פרמטרים'!$O$4),'טבלת פרמטרים'!$P$4,IF(EXACT(Q65,'טבלת פרמטרים'!$O$5),'טבלת פרמטרים'!$P$5,IF(EXACT(Q65,'טבלת פרמטרים'!$O$6),'טבלת פרמטרים'!$P$6,IF(EXACT(Q65,'טבלת פרמטרים'!$O$7),'טבלת פרמטרים'!$P$7,"")))))) -> 0
A66: 65 | B66: 43185 | C66: 43195 | D66: מהלך טיפול | E66: נפגע | F66: נפגע יחיד | G66: חד פעמי | H66: טעות אנוש | I66: עבודת בוקר | J66: מאיץ4/מאיץ5 | K66: 3D | L66: תיק רגיל | M66: ללא | N66: שינוי נוהל קיים | O66: =IF(ISBLANK(D66),"",IF(D66='טבלת פרמטרים'!$A$9,1,0)+IF(E66='טבלת פרמטרים'!$B$5,2,1)+IF(F66='טבלת פרמטרים'!$C$5,3,IF(F66='טבלת פרמטרים'!$C$4,1,0))+IF(G66='טבלת פרמטרים'!$D$3,2,0)+IF(M66='טבלת פרמטרים'!$J$4,2,IF(M66='טבלת פרמטרים'!$J$3,1,0))+IF(N66='טבלת פרמטרים'!$K$6,3,IF(OR(N66='טבלת פרמטרים'!$K$4,N66='טבלת פרמטרים'!$K$5),2,IF(N66='טבלת פרמטרים'!$K$3,1,0)))) -> 6 | P66: לא נפגע | Q66: שוני במנה אבסולוטית מהמרשם קטן מ- 5% לכל איבר | R66: =IF(ISNUMBER(T66),T66+O66,O66) -> 7 | S66: =IF(EXACT(P66,'טבלת פרמטרים'!$M$2),'טבלת פרמטרים'!$N$2,IF(EXACT(P66,'טבלת פרמטרים'!$M$3),'טבלת פרמטרים'!$N$3,IF(EXACT(P66,'טבלת פרמטרים'!$M$4),'טבלת פרמטרים'!$N$4,IF(EXACT(P66,'טבלת פרמטרים'!$M$5),'טבלת פרמטרים'!$N$5,IF(EXACT(P66,'טבלת פרמטרים'!$M$6),'טבלת פרמטרים'!$N$6,IF(EXACT(P66,'טבלת פרמטרים'!$M$7),'טבלת פרמטרים'!$N$7,IF(EXACT(P66,'טבלת פרמטרים'!$M$8),'טבלת פרמטרים'!$N$8,IF(EXACT(P66,'טבלת פרמטרים'!$M$9),'טבלת פרמטרים'!$N$9,"")))))))) -> 0 | T66: =IF(EXACT(Q66,'טבלת פרמטרים'!$O$2),'טבלת פרמטרים'!$P$2,IF(EXACT(Q66,'טבלת פרמטרים'!$O$3),'טבלת פרמטרים'!$P$3,IF(EXACT(Q66,'טבלת פרמטרים'!$O$4),'טבלת פרמטרים'!$P$4,IF(EXACT(Q66,'טבלת פרמטרים'!$O$5),'טבלת פרמטרים'!$P$5,IF(EXACT(Q66,'טבלת פרמטרים'!$O$6),'טבלת פרמטרים'!$P$6,IF(EXACT(Q66,'טבלת פרמטרים'!$O$7),'טבלת פרמטרים'!$P$7,"")))))) -> 1
...

Sheet Event summary
A1: ='Incident Reporting'!A1 -> מספר סידורי | B1: מילון מונחים | C1: תקציר מקרה | D1: מסקנות ישיבה | E1: תאריך ישיבת QI | F1: נוכחים | G1: דו"ח חיצוני | H1: מועד דיווח | I1: נשלח בתאריך
A2: ='Incident Reporting'!A2 -> 1
A3: ='Incident Reporting'!A3 -> 2
A4: ='Incident Reporting'!A4 -> 3
A5: ='Incident Reporting'!A5 -> 4
A6: ='Incident Reporting'!A6 -> 5
A7: ='Incident Reporting'!A7 -> 6
A8: ='Incident Reporting'!A8 -> 7
A9: ='Incident Reporting'!A9 -> 8
A10: ='Incident Reporting'!A10 -> 9
A11: ='Incident Reporting'!A11 -> 10
A12: ='Incident Reporting'!A12 -> 11
A13: ='Incident Reporting'!A13 -> 12
... A37: ='Incident Reporting'!A37 -> 36
A38: ='Incident Reporting'!A38 -> 37 | B38: היעדר תיעוד | C38: רישום לקוי, היעדר תיעוד במערכת ה-ARIA
A39: ='Incident Reporting'!A39 -> 38 | B39: תכנון שגוי | C39: תכנון שגוי - חישוב שגוי אלקטרונים
A40: ='Incident Reporting'!A40 -> 39 | B40: תכנון שגוי | C40: חפיפה בין השדות,
A41: ='Incident Reporting'!A41 -> 40 | B41: היעדר מרשם | C41: מתן טיפול בהיעדר מרשם, מתן טיפול עם מנה גבוהה מהרצוי
A42: ='Incident Reporting'!A42 -> 41 | B42: היעדר מרשם | C42: טיפול חוזר עם היעדר מרשם עדכני
A43: ='Incident Reporting'!A43 -> 42 | B43: מתן טיפול באופן שגוי | C43: טיפול בתוכנית של אדם אחר, סידור לקוי של מספר תכניות.
A44: ='Incident Reporting'!A44 -> 43 | B44: תיעוד לא תקין | C44: רישום אביזר לא נכון, טיפול נכון
A45: ='Incident Reporting'!A45 -> 44 | B45: היעדר צילומים | C45: תחילת טיפול ללא צילום, 2 טיפולים ראשונים
A46: ='Incident Reporting'!A46 -> 45 | B46: היעדר תיעוד | C46: היעדר תיעוד ורישום למרכזי הטיפול
A47: ='Incident Reporting'!A47 -> 46 | B47: אי עמידה בזמנים | C47: אי עמידה בזמנים, תיק לא מוכן
A48: ='Incident Reporting'!A48 -> 47 | B48: מתן טיפול באופן שגוי | C48: מתן שתי תכניות בו זמנית למרות הצורך בפיצולן
A49: ='Incident Reporting'!A49 -> 48 | B49: תקשורת לקויה | C49: היעדר העברת מידע על שינוי מרכז
... A101: ='Incident Reporting'!A101 -> 100 | B101: תכנון שגוי | C101: טיפול ברכי ברונכוס, קטטר נחתך - היה קצר מדי ולא ניתן לטפל
A102: ='Incident Reporting'!A102 -> 101
A103: ='Incident Reporting'!A103 -> 102
A104: ='Incident Reporting'!A104 -> 103
A105: ='Incident Reporting'!A105 -> 104 | B105: בעיות קיבוע | C105: בעיות קיבוע - אמצעי קיבוע פגום. לא ניתן היה להשכיב מטופל על מיטת SRS בסימוליצה עקב שינוי במתקן.
A106: ='Incident Reporting'!A106 -> 105
A107: ='Incident Reporting'!A107 -> 106
A108: ='Incident Reporting'!A108 -> 107
A109: ='Incident Reporting'!A109 -> 108
A110: ='Incident Reporting'!A110 -> 109
A111: ='Incident Reporting'!A111 -> 110
A112: ='Incident Reporting'!A112 -> 111
A113: ='Incident Reporting'!A113 -> 112
A114: ='Incident Reporting'!A114 -> 113
...

Sheet Taxonomy
A1: מילון מונחים | B1: שכיחות | D1: =SUM(B:B) -> 799 | E1: key word
A2: תיעוד לא תקין | B2: =COUNTIF('Event summary'!B:B,A2) -> 157 | C2: =IF(OR(ISBLANK($F$1),G2<>1),"",A2) | D2: =B2/$D$1 -> 0.19649562 | G2: =TYPE(SEARCH($F$1,A2)) -> 1
A3: תקשורת לקויה | B3: =COUNTIF('Event summary'!B:B,A3) -> 74 | C3: =IF(OR(ISBLANK($F$1),G3<>1),"",A3) | D3: =B3/$D$1 -> 0.09261577 | G3: =TYPE(SEARCH($F$1,A3)) -> 1
A4: מתן טיפול באופן שגוי | B4: =COUNTIF('Event summary'!B:B,A4) -> 69 | C4: =IF(OR(ISBLANK($F$1),G4<>1),"",A4) | D4: =B4/$D$1 -> 0.086357947 | G4: =TYPE(SEARCH($F$1,A4)) -> 1
A5: העברת מידע | B5: =COUNTIF('Event summary'!B:B,A5) -> 69 | C5: =IF(OR(ISBLANK($F$1),G5<>1),"",A5) | D5: =B5/$D$1 -> 0.086357947 | G5: =TYPE(SEARCH($F$1,A5)) -> 1
A6: סריקה לא תקינה | B6: =COUNTIF('Event summary'!B:B,A6) -> 53 | C6: =IF(OR(ISBLANK($F$1),G6<>1),"",A6) | D6: =B6/$D$1 -> 0.066332916 | G6: =TYPE(SEARCH($F$1,A6)) -> 1
A7: תכנון שגוי | B7: =COUNTIF('Event summary'!B:B,A7) -> 56 | C7: =IF(OR(ISBLANK($F$1),G7<>1),"",A7) | D7: =B7/$D$1 -> 0.07008761 | G7: =TYPE(SEARCH($F$1,A7)) -> 1
A8: אי עמידה בזמנים | B8: =COUNTIF('Event summary'!B:B,A8) -> 54 | C8: =IF(OR(ISBLANK($F$1),G8<>1),"",A8) | D8: =B8/$D$1 -> 0.067584481 | G8: =TYPE(SEARCH($F$1,A8)) -> 1
